Workbook

Sheet Dashboard
B1: Cu Removal from Recycled Steel — CALPHAD Screening Workbook
B2: MSE 4381 Capstone | Honda R&D Americas | TCOX14 Database | Spring 2026
B4: PROJECT SUMMARY
B5: Recycled steel contains 0.25-0.3% Cu from wiring and motors, causing hot shortness above 0.1%.
B6: This workbook screens 17 ceramic oxides for Cu removal via ternary compound formation (Cu + MOx + O2 -> CuMOy).
B7: All 16 modeled ternary reactions are thermodynamically favorable (negative dG). Top candidates: CuFe2O4 (-112 kJ), Cu3V2O8 (-109 kJ), CuMn2O4 (-64 kJ).
B8: At steelmaking temperatures (1800K), Cu capture occurs via dissolution into oxide slag, not crystalline compound formation.
B10: HOW TO USE THIS WORKBOOK
B11: Tabs are color-coded. Click any formula cell in a blue tab to trace it back to source data.
B13: Tab | C13: Color | D13: Purpose | E13: Key Contents
B14: Dashboard | C14: BLUE | D14: Analysis | E14: This tab. Project overview, navigation, key figures.
B15: Screening_Summary | C15: BLUE | D15: Analysis | E15: One row per oxide: binary verdict, ternary verdict, tier rank.
B16: CuFe2O4_DeepDive | C16: BLUE | D16: Analysis | E16: Decompose CuFe2O4 reaction into Cu-capture vs Fe-oxidation.
B17: Activity_and_Slag | C17: BLUE | D17: Analysis | E17: Dilute Cu penalty, gamma sensitivity, slag basicity effects.
B18: Normalization | C18: BLUE | D18: Analysis | E18: Full stoichiometry (17 binary + 18 ternary) + 2 worked examples.
B19: Screening_Table | C19: GREEN | D19: Results | E19: Binary oxide dG at 3 temperatures + physical properties.
B20: Ternary_Verdicts | C20: GREEN | D20: Results | E20: Ternary product dG at 3 temperatures + phase data.
B21: Activity_Corrected | C21: GREEN | D21: Results | E21: Activity-corrected dG for all products across temperature.
B22: OX_Gibbs | C22: GRAY | D22: Raw Data | E22: Oxide Gibbs energies (18 oxides, 500-2000K, TCOX14).
B23: Ternary_Rxns | C23: GRAY | D23: Raw Data | E23: Ternary reaction energies (16 systems x 23 temps).
B24: dG_Top6 | C24: GRAY | D24: Raw Data | E24: Fine-resolution dG vs T for top 6 candidates (25K steps).
... B28: Phase_Map | C28: GRAY | D28: Raw Data | E28: 20x20 ternary composition grid phase mapping at 1800K.
B30: DATA PROVENANCE
B31: Source Tab | C31: Source CSV | D31: Database | E31: Date | F31: Generating Script
B32: OX_Gibbs | C32: oxide_gibbs_energies.csv | D32: TCOX14+SSUB3 | E32: Mar 12 | F32: extract_oxide_gibbs.py
B33: Ternary_Rxns | C33: ternary_reaction_energies.csv | D33: TCOX14 | E33: Mar 13 | F33: extract_ternary_reactions.py
B34: dG_Top6 | C34: dG_vs_T_top6.csv | D34: TCOX14 | E34: Mar 13 | F34: dG_vs_T_top6.py
B35: CuFe2O4_Raw | C35: cufe2o4_alternative_reaction.csv | D35: TCOX14 | E35: Mar 13 | F35: cufe2o4_alternative_reaction.py
B36: Cu_Activity | C36: cu_activity_vs_oxide.csv | D36: TCOX14 | E36: Mar 13 | F36: cu_activity_vs_oxide.py
B37: Slag_Effects | C37: slag_composition_effects.csv | D37: TCOX14 | E37: Mar 13 | F37: slag_composition_effects.py
B38: Phase_Map | C38: ternary_phase_map_1800K.csv | D38: TCOX14 | E38: Mar 13 | F38: ternary_phase_map_1800K.py
B39: Activity_Corrected | C39: activity_corrected_dG.csv | D39: (derived) | E39: Mar 13 | F39: compute_activity_corrected_dG.py
B40: Screening_Table | C40: screening_table.csv | D40: (derived) | E40: Mar 13 | F40: build_combined_screening.py
B41: Ternary_Verdicts | C41: ternary_screening_results.csv | D41: (derived) | E41: Mar 13 | F41: compute_ternary_dG.py
B44: KEY FIGURES
B45: Figure 1. Reaction driving force vs temperature for top 6 ternary Cu-capture candidates (25K resolution, TCOX14). Data: dG_Top6 tab.
B72: Figure 2. Activity-corrected dG comparison: pure reference vs dilute Cu (X_Cu=0.003, gamma=8.5). Data: Activity_and_Slag tab.
B93: Figure 3. CuFe2O4 reaction decomposition: total dG split into Cu-capture and Fe-oxidation contributions. Data: CuFe2O4_DeepDive tab.
B113: Figure 4. Effect of slag basicity on Cu activity: MnO:SiO2 and Al2O3:SiO2 ratios at 1800K. Data: Slag_Effects tab.
B141: Generated by build_unified_xlsx.py | All plots: matplotlib (colorblind-friendly palette per CLAUDE.md)

Sheet Screening_Summary
A1: SCREENING SUMMARY — Binary oxide stability + ternary Cu-capture potential for 17 candidate oxides
A2: All values reference the green/gray backing tabs. Click any formula cell to trace its source.
A3: Oxide | B3: Formula | C3: Density (g/cm³) | D3: Melting Point (°C) | E3: Floats on Steel? | F3: ΔG_binary @ 1527°C (kJ/mol O₂) | G3: Binary Verdict | H3: Best Ternary Product | I3: ΔG_ternary @ 1527°C (kJ) | J3: Ternary Verdict | K3: Tier
A4: =Screening_Table!A4 -> MgO | B4: =Screening_Table!B4 -> MgO | C4: =Screening_Table!C4 -> 3.58 | D4: =Screening_Table!D4 -> 2852 | E4: =Screening_Table!E4 -> Yes | F4: =Screening_Table!I4 -> 642.9 | G4: =IF(ISNUMBER(F4),IF(F4<0,"Cu REDUCES","STABLE"),"N/A") -> STABLE | H4: =Ternary_Verdicts!A14 -> CuMgO2 | I4: =Ternary_Verdicts!G14 -> -26.1 | J4: =IF(ISNUMBER(I4),IF(I4<0,"Cu CAPTURED","NO CAPTURE"),"N/A") -> Cu CAPTURED | K4: =IF(ISNUMBER(I4),IF(I4<-50,"STRONG",IF(I4<-25,"MODERATE","WEAK")),"N/A") -> MODERATE
A5: =Screening_Table!A5 -> Al₂O₃ | B5: =Screening_Table!B5 -> Al2O3 | C5: =Screening_Table!C5 -> 3.95 | D5: =Screening_Table!D5 -> 2072 | E5: =Screening_Table!E5 -> Yes | F5: =Screening_Table!I5 -> 644.8 | G5: =IF(ISNUMBER(F5),IF(F5<0,"Cu REDUCES","STABLE"),"N/A") -> STABLE | H5: =Ternary_Verdicts!A4 -> CuAl2O4 | I5: =Ternary_Verdicts!G4 -> -32.3 | J5: =IF(ISNUMBER(I5),IF(I5<0,"Cu CAPTURED","NO CAPTURE"),"N/A") -> Cu CAPTURED | K5: =IF(ISNUMBER(I5),IF(I5<-50,"STRONG",IF(I5<-25,"MODERATE","WEAK")),"N/A") -> MODERATE
A6: =Screening_Table!A6 -> CaO | B6: =Screening_Table!B6 -> CaO | C6: =Screening_Table!C6 -> 3.34 | D6: =Screening_Table!D6 -> 2613 | E6: =Screening_Table!E6 -> Yes | F6: =Screening_Table!I6 -> 791.3 | G6: =IF(ISNUMBER(F6),IF(F6<0,"Cu REDUCES","STABLE"),"N/A") -> STABLE | H6: =Ternary_Verdicts!A15 -> CuCaO2 | I6: =Ternary_Verdicts!G15 -> -30.7 | J6: =IF(ISNUMBER(I6),IF(I6<0,"Cu CAPTURED","NO CAPTURE"),"N/A") -> Cu CAPTURED | K6: =IF(ISNUMBER(I6),IF(I6<-50,"STRONG",IF(I6<-25,"MODERATE","WEAK")),"N/A") -> MODERATE
A7: =Screening_Table!A7 -> ZrO₂ | B7: =Screening_Table!B7 -> ZrO2 | C7: =Screening_Table!C7 -> 5.68 | D7: =Screening_Table!D7 -> 2715 | E7: =Screening_Table!E7 -> Yes | F7: =Screening_Table!I7 -> 675.7 | G7: =IF(ISNUMBER(F7),IF(F7<0,"Cu REDUCES","STABLE"),"N/A") -> STABLE | H7: =Ternary_Verdicts!A16 -> CuZrO3 | I7: =Ternary_Verdicts!G16 -> -25.3 | J7: =IF(ISNUMBER(I7),IF(I7<0,"Cu CAPTURED","NO CAPTURE"),"N/A") -> Cu CAPTURED | K7: =IF(ISNUMBER(I7),IF(I7<-50,"STRONG",IF(I7<-25,"MODERATE","WEAK")),"N/A") -> MODERATE
A8: =Screening_Table!A8 -> Cr₂O₃ | B8: =Screening_Table!B8 -> Cr2O3 | C8: =Screening_Table!C8 -> 5.22 | D8: =Screening_Table!D8 -> 2435 | E8: =Screening_Table!E8 -> Yes | F8: =Screening_Table!I8 -> 354.8 | G8: =IF(ISNUMBER(F8),IF(F8<0,"Cu REDUCES","STABLE"),"N/A") -> STABLE | H8: =Ternary_Verdicts!A6 -> CuCr2O4 | I8: =Ternary_Verdicts!G6 -> -30 | J8: =IF(ISNUMBER(I8),IF(I8<0,"Cu CAPTURED","NO CAPTURE"),"N/A") -> Cu CAPTURED | K8: =IF(ISNUMBER(I8),IF(I8<-50,"STRONG",IF(I8<-25,"MODERATE","WEAK")),"N/A") -> MODERATE
A9: =Screening_Table!A9 -> TiO₂ | B9: =Screening_Table!B9 -> TiO2 | C9: =Screening_Table!C9 -> 4.23 | D9: =Screening_Table!D9 -> 1843 | E9: =Screening_Table!E9 -> Yes | F9: =Screening_Table!I9 -> 531.3 | G9: =IF(ISNUMBER(F9),IF(F9<0,"Cu REDUCES","STABLE"),"N/A") -> STABLE | H9: =Ternary_Verdicts!A11 -> CuTiO3 | I9: =Ternary_Verdicts!G11 -> -36.8 | J9: =IF(ISNUMBER(I9),IF(I9<0,"Cu CAPTURED","NO CAPTURE"),"N/A") -> Cu CAPTURED | K9: =IF(ISNUMBER(I9),IF(I9<-50,"STRONG",IF(I9<-25,"MODERATE","WEAK")),"N/A") -> MODERATE
A10: =Screening_Table!A10 -> SiO₂ | B10: =Screening_Table!B10 -> SiO2 | C10: =Screening_Table!C10 -> 2.65 | D10: =Screening_Table!D10 -> 1713 | E10: =Screening_Table!E10 -> Yes | F10: =Screening_Table!I10 -> 502.7 | G10: =IF(ISNUMBER(F10),IF(F10<0,"Cu REDUCES","STABLE"),"N/A") -> STABLE | H10: =Ternary_Verdicts!A13 -> Cu2SiO4 | I10: =Ternary_Verdicts!G13 -> -52.2 | J10: =IF(ISNUMBER(I10),IF(I10<0,"Cu CAPTURED","NO CAPTURE"),"N/A") -> Cu CAPTURED | K10: =IF(ISNUMBER(I10),IF(I10<-50,"STRONG",IF(I10<-25,"MODERATE","WEAK")),"N/A") -> STRONG
A11: =Screening_Table!A11 -> MnO | B11: =Screening_Table!B11 -> MnO | C11: =Screening_Table!C11 -> 5.43 | D11: =Screening_Table!D11 -> 1842 | E11: =Screening_Table!E11 -> Yes | F11: =Screening_Table!I11 -> 408.9 | G11: =IF(ISNUMBER(F11),IF(F11<0,"Cu REDUCES","STABLE"),"N/A") -> STABLE | H11: =Ternary_Verdicts!A7 -> CuMn2O4 | I11: =Ternary_Verdicts!G7 -> -64.4 | J11: =IF(ISNUMBER(I11),IF(I11<0,"Cu CAPTURED","NO CAPTURE"),"N/A") -> Cu CAPTURED | K11: =IF(ISNUMBER(I11),IF(I11<-50,"STRONG",IF(I11<-25,"MODERATE","WEAK")),"N/A") -> STRONG
A12: =Screening_Table!A12 -> FeO | B12: =Screening_Table!B12 -> FeO | C12: =Screening_Table!C12 -> 5.74 | D12: =Screening_Table!D12 -> 1377 | E12: =Screening_Table!E12 -> Yes | F12: =Screening_Table!I12 -> 213.8 | G12: =IF(ISNUMBER(F12),IF(F12<0,"Cu REDUCES","STABLE"),"N/A") -> STABLE | H12: =Ternary_Verdicts!A8 -> CuFe2O4 | I12: =Ternary_Verdicts!G8 -> -111.9 | J12: =IF(ISNUMBER(I12),IF(I12<0,"Cu CAPTURED","NO CAPTURE"),"N/A") -> Cu CAPTURED | K12: =IF(ISNUMBER(I12),IF(I12<-50,"STRONG",IF(I12<-25,"MODERATE","WEAK")),"N/A") -> STRONG
A13: =Screening_Table!A13 -> CuO | B13: =Screening_Table!B13 -> CuO | C13: =Screening_Table!C13 -> 6.31 | D13: =Screening_Table!D13 -> 1326 | E13: =Screening_Table!E13 -> Yes | F13: =Screening_Table!I13 -> -41 | G13: =IF(ISNUMBER(F13),IF(F13<0,"Cu REDUCES","STABLE"),"N/A") -> Cu REDUCES | H13: No data | I13: N/A | J13: N/A | K13: N/A
A14: =Screening_Table!A14 -> NiO | B14: =Screening_Table!B14 -> NiO | C14: =Screening_Table!C14 -> 6.67 | D14: =Screening_Table!D14 -> 1955 | E14: =Screening_Table!E14 -> Yes | F14: =Screening_Table!I14 -> 76 | G14: =IF(ISNUMBER(F14),IF(F14<0,"Cu REDUCES","STABLE"),"N/A") -> STABLE | H14: =Ternary_Verdicts!A17 -> CuNiO2 | I14: =Ternary_Verdicts!G17 -> -27.3 | J14: =IF(ISNUMBER(I14),IF(I14<0,"Cu CAPTURED","NO CAPTURE"),"N/A") -> Cu CAPTURED | K14: =IF(ISNUMBER(I14),IF(I14<-50,"STRONG",IF(I14<-25,"MODERATE","WEAK")),"N/A") -> MODERATE
A15: =Screening_Table!A15 -> CoO | B15: =Screening_Table!B15 -> CoO | C15: =Screening_Table!C15 -> 6.44 | D15: =Screening_Table!D15 -> 1830 | E15: =Screening_Table!E15 -> Yes | F15: =Screening_Table!I15 -> 126.6 | G15: =IF(ISNUMBER(F15),IF(F15<0,"Cu REDUCES","STABLE"),"N/A") -> STABLE | H15: =Ternary_Verdicts!A18 -> CuCo2O4 | I15: =Ternary_Verdicts!G18 -> -35.8 | J15: =IF(ISNUMBER(I15),IF(I15<0,"Cu CAPTURED","NO CAPTURE"),"N/A") -> Cu CAPTURED | K15: =IF(ISNUMBER(I15),IF(I15<-50,"STRONG",IF(I15<-25,"MODERATE","WEAK")),"N/A") -> MODERATE
A16: =Screening_Table!A16 -> PbO | B16: =Screening_Table!B16 -> PbO | C16: =Screening_Table!C16 -> 9.53 | D16: =Screening_Table!D16 -> 888 | E16: =Screening_Table!E16 -> No | F16: =Screening_Table!I16 -> 136.2 | G16: =IF(ISNUMBER(F16),IF(F16<0,"Cu REDUCES","STABLE"),"N/A") -> STABLE | H16: No data | I16: N/A | J16: N/A | K16: N/A
A17: =Screening_Table!A17 -> B₂O₃ | B17: =Screening_Table!B17 -> B2O3 | C17: =Screening_Table!C17 -> 2.55 | D17: =Screening_Table!D17 -> 450 | E17: =Screening_Table!E17 -> Yes | F17: =Screening_Table!I17 -> 481.1 | G17: =IF(ISNUMBER(F17),IF(F17<0,"Cu REDUCES","STABLE"),"N/A") -> STABLE | H17: =Ternary_Verdicts!A21 -> CuB2O4 | I17: =Ternary_Verdicts!G21 -> -47.7 | J17: =IF(ISNUMBER(I17),IF(I17<0,"Cu CAPTURED","NO CAPTURE"),"N/A") -> Cu CAPTURED | K17: =IF(ISNUMBER(I17),IF(I17<-50,"STRONG",IF(I17<-25,"MODERATE","WEAK")),"N/A") -> MODERATE
A18: =Screening_Table!A18 -> V₂O₅ | B18: =Screening_Table!B18 -> V2O5 | C18: =Screening_Table!C18 -> 3.36 | D18: =Screening_Table!D18 -> 690 | E18: =Screening_Table!E18 -> Yes | F18: =Screening_Table!I18 -> 259.4 | G18: =IF(ISNUMBER(F18),IF(F18<0,"Cu REDUCES","STABLE"),"N/A") -> STABLE | H18: =Ternary_Verdicts!A10 -> Cu3V2O8 | I18: =Ternary_Verdicts!G10 -> -109.2 | J18: =IF(ISNUMBER(I18),IF(I18<0,"Cu CAPTURED","NO CAPTURE"),"N/A") -> Cu CAPTURED | K18: =IF(ISNUMBER(I18),IF(I18<-50,"STRONG",IF(I18<-25,"MODERATE","WEAK")),"N/A") -> STRONG
A19: =Screening_Table!A19 -> La₂O₃ | B19: =Screening_Table!B19 -> La2O3 | C19: =Screening_Table!C19 -> 6.51 | D19: =Screening_Table!D19 -> 2315 | E19: =Screening_Table!E19 -> Yes | F19: =Screening_Table!I19 -> 766.3 | G19: =IF(ISNUMBER(F19),IF(F19<0,"Cu REDUCES","STABLE"),"N/A") -> STABLE | H19: =Ternary_Verdicts!A19 -> CuLaO2 | I19: =Ternary_Verdicts!G19 -> -27.8 | J19: =IF(ISNUMBER(I19),IF(I19<0,"Cu CAPTURED","NO CAPTURE"),"N/A") -> Cu CAPTURED | K19: =IF(ISNUMBER(I19),IF(I19<-50,"STRONG",IF(I19<-25,"MODERATE","WEAK")),"N/A") -> MODERATE
A20: =Screening_Table!A20 -> CeO₂ | B20: =Screening_Table!B20 -> CeO2 | C20: =Screening_Table!C20 -> 7.22 | D20: =Screening_Table!D20 -> 2400 | E20: =Screening_Table!E20 -> No | F20: =Screening_Table!I20 -> 1240.7 | G20: =IF(ISNUMBER(F20),IF(F20<0,"Cu REDUCES","STABLE"),"N/A") -> STABLE | H20: No data | I20: N/A | J20: N/A | K20: N/A
A22: TOP CANDIDATES
A23: Product | B23: Parent Oxide | C23: Reaction | D23: ΔG @ 1527°C (kJ) | E23: Named Phase | F23: Mechanism | G23: Tier
A24: CuFe₂O₄ | B24: FeO | C24: Cu + 2FeO + O₂ → CuFe₂O₄ | D24: =Ternary_Verdicts!G8 -> -111.9 | E24: SPINEL#1 (to 1700K) | F24: Spinel trapping | G24: STRONG
A25: Cu₃V₂O₈ | B25: V₂O₅ | C25: 3Cu + V₂O₅ + 1.5O₂ → Cu₃V₂O₈ | D25: =Ternary_Verdicts!G10 -> -109.2 | E25: none (liquid) | F25: Vanadate slag dissolution | G25: STRONG
A26: CuMn₂O₄ | B26: MnO | C26: Cu + 2MnO + O₂ → CuMn₂O₄ | D26: =Ternary_Verdicts!G7 -> -64.4 | E26: SPINEL#1 (to 1700K) | F26: Spinel trapping | G26: STRONG
A27: Cu₂SiO₄ | B27: SiO₂ | C27: 2Cu + SiO₂ + O₂ → Cu₂SiO₄ | D27: =Ternary_Verdicts!G13 -> -52.2 | E27: none (liquid) | F27: Silicate slag dissolution | G27: STRONG

Sheet CuFe2O4_DeepDive
A1: CuFe2O4 DEEP DIVE — Decomposing the strongest candidate into Cu-capture vs Fe-oxidation
A2: The total CuFe2O4 formation reaction (Cu + 2FeO + O2) is split into two contributions. Columns E-G are formulas referencing the CuFe2O4_Raw tab.
A3: T (K) | B3: T (°C) | C3: dG_original (kJ) | D3: dG_alternative (kJ) | E3: dG_Fe_oxidation (kJ) | F3: Cu-capture (%) | G3: Fe-oxidation (%)
A4: =CuFe2O4_Raw!A4 -> 800 | B4: =A4-273.15 -> 526.85 | C4: =CuFe2O4_Raw!L4 -> -271.03187 | D4: =CuFe2O4_Raw!J4 -> -85.340853 | E4: =C4-D4 -> -185.69102 | F4: =IF(C4<>0,D4/C4*100,0) -> 31.487386 | G4: =100-F4 -> 68.512614
A5: =CuFe2O4_Raw!A5 -> 850 | B5: =A5-273.15 -> 576.85 | C5: =CuFe2O4_Raw!L5 -> -262.71414 | D5: =CuFe2O4_Raw!J5 -> -82.376584 | E5: =C5-D5 -> -180.33756 | F5: =IF(C5<>0,D5/C5*100,0) -> 31.355976 | G5: =100-F5 -> 68.644024
A6: =CuFe2O4_Raw!A6 -> 900 | B6: =A6-273.15 -> 626.85 | C6: =CuFe2O4_Raw!L6 -> -253.63898 | D6: =CuFe2O4_Raw!J6 -> -79.384097 | E6: =C6-D6 -> -174.25488 | F6: =IF(C6<>0,D6/C6*100,0) -> 31.298066 | G6: =100-F6 -> 68.701934
A7: =CuFe2O4_Raw!A7 -> 950 | B7: =A7-273.15 -> 676.85 | C7: =CuFe2O4_Raw!L7 -> -244.63346 | D7: =CuFe2O4_Raw!J7 -> -76.337724 | E7: =C7-D7 -> -168.29574 | F7: =IF(C7<>0,D7/C7*100,0) -> 31.20494 | G7: =100-F7 -> 68.79506
A8: =CuFe2O4_Raw!A8 -> 1000 | B8: =A8-273.15 -> 726.85 | C8: =CuFe2O4_Raw!L8 -> -235.69271 | D8: =CuFe2O4_Raw!J8 -> -73.247969 | E8: =C8-D8 -> -162.44474 | F8: =IF(C8<>0,D8/C8*100,0) -> 31.077741 | G8: =100-F8 -> 68.922259
A9: =CuFe2O4_Raw!A9 -> 1050 | B9: =A9-273.15 -> 776.85 | C9: =CuFe2O4_Raw!L9 -> -226.81218 | D9: =CuFe2O4_Raw!J9 -> -70.178773 | E9: =C9-D9 -> -156.6334 | F9: =IF(C9<>0,D9/C9*100,0) -> 30.94136 | G9: =100-F9 -> 69.05864
A10: =CuFe2O4_Raw!A10 -> 1100 | B10: =A10-273.15 -> 826.85 | C10: =CuFe2O4_Raw!L10 -> -217.98972 | D10: =CuFe2O4_Raw!J10 -> -67.143947 | E10: =C10-D10 -> -150.84578 | F10: =IF(C10<>0,D10/C10*100,0) -> 30.801428 | G10: =100-F10 -> 69.198572
A11: =CuFe2O4_Raw!A11 -> 1150 | B11: =A11-273.15 -> 876.85 | C11: =CuFe2O4_Raw!L11 -> -209.22461 | D11: =CuFe2O4_Raw!J11 -> -64.151393 | E11: =C11-D11 -> -145.07321 | F11: =IF(C11<>0,D11/C11*100,0) -> 30.661495 | G11: =100-F11 -> 69.338505
A12: =CuFe2O4_Raw!A12 -> 1200 | B12: =A12-273.15 -> 926.85 | C12: =CuFe2O4_Raw!L12 -> -200.51353 | D12: =CuFe2O4_Raw!J12 -> -61.206737 | E12: =C12-D12 -> -139.30679 | F12: =IF(C12<>0,D12/C12*100,0) -> 30.524992 | G12: =100-F12 -> 69.475008
A13: =CuFe2O4_Raw!A13 -> 1250 | B13: =A13-273.15 -> 976.85 | C13: =CuFe2O4_Raw!L13 -> -191.85794 | D13: =CuFe2O4_Raw!J13 -> -58.314513 | E13: =C13-D13 -> -133.54343 | F13: =IF(C13<>0,D13/C13*100,0) -> 30.394631 | G13: =100-F13 -> 69.605369
A14: =CuFe2O4_Raw!A14 -> 1300 | B14: =A14-273.15 -> 1026.85 | C14: =CuFe2O4_Raw!L14 -> -183.25921 | D14: =CuFe2O4_Raw!J14 -> -55.478722 | E14: =C14-D14 -> -127.78049 | F14: =IF(C14<>0,D14/C14*100,0) -> 30.27336 | G14: =100-F14 -> 69.72664
A15: =CuFe2O4_Raw!A15 -> 1350 | B15: =A15-273.15 -> 1076.85 | C15: =CuFe2O4_Raw!L15 -> -174.71743 | D15: =CuFe2O4_Raw!J15 -> -52.703069 | E15: =C15-D15 -> -122.01436 | F15: =IF(C15<>0,D15/C15*100,0) -> 30.164746 | G15: =100-F15 -> 69.835254
... A26: =CuFe2O4_Raw!A26 -> 1900 | B26: =A26-273.15 -> 1626.85 | C26: =CuFe2O4_Raw!L26 -> -102.69378 | D26: =CuFe2O4_Raw!J26 -> -46.715289 | E26: =C26-D26 -> -55.978493 | F26: =IF(C26<>0,D26/C26*100,0) -> 45.489891 | G26: =100-F26 -> 54.510109
A27: AVERAGE | C27: =AVERAGE(C4:C26) -> -178.83129 | D27: =AVERAGE(D4:D26) -> -57.518394 | E27: =AVERAGE(E4:E26) -> -121.31289 | F27: =AVERAGE(F4:F26) -> 32.967727 | G27: =AVERAGE(G4:G26) -> 67.032273

Sheet Activity_and_Slag
A1: ACTIVITY AND SLAG EFFECTS — What happens under real steelmaking conditions?
A2: Section 1: Dilute Cu penalty (editable X_Cu and gamma_Cu). Section 2: Gamma sensitivity sweep. Section 3: Slag basicity effects from Slag_Effects tab.
A4: Parameter | B4: Symbol | C4: Value | D4: Unit / Note
A5: Cu mole fraction in steel | B5: X_Cu | C5: 0.003 | D5: ~0.3 wt% Cu (EDITABLE)
A6: Raoultian activity coefficient | B6: γ_Cu | C6: 8.5 | D6: Literature range: 5-13 (EDITABLE)
A7: Cu activity in liquid Fe | B7: a_Cu | C7: =C5*C6 -> 0.0255 | D7: X_Cu × γ_Cu (formula in C7)
A8: Temperature | B8: T | C8: 1800 | D8: K (steelmaking)
A9: Gas constant | B9: R | C9: 8.314 | D9: J/(mol·K)
A10: Penalty per Cu atom consumed | B10: -RT·ln(a_Cu) | C10: =-C9*C8*LN(C7)/1000 -> 54.908469 | D10: kJ/mol (positive = less favorable)
A12: ACTIVITY-CORRECTED ΔG AT 1800 K
A13: Product | B13: Parent Oxide | C13: n_Cu | D13: ΔG° (kJ) | E13: Cu Penalty (kJ) | F13: ΔG_eff (kJ) | G13: Verdict | H13: ΔG per Cu (kJ)
A14: CuFe2O4 | B14: FeO | C14: 1 | D14: =Ternary_Rxns!N116 -> -111.8803 | E14: =C14*$C$10 -> 54.908469 | F14: =D14+E14 -> -56.971833 | G14: =IF(F14<-10,"ROBUST",IF(F14<0,"MARGINAL",IF(F14<15,"UNCERTAIN","UNFAVORABLE"))) -> ROBUST | H14: =D14/C14 -> -111.8803
A15: CuMn2O4 | B15: MnO | C15: 1 | D15: =Ternary_Rxns!N93 -> -64.442552 | E15: =C15*$C$10 -> 54.908469 | F15: =D15+E15 -> -9.5340833 | G15: =IF(F15<-10,"ROBUST",IF(F15<0,"MARGINAL",IF(F15<15,"UNCERTAIN","UNFAVORABLE"))) -> MARGINAL | H15: =D15/C15 -> -64.442552
A16: CuB2O4 | B16: B2O3 | C16: 1 | D16: =Ternary_Rxns!N415 -> -47.711524 | E16: =C16*$C$10 -> 54.908469 | F16: =D16+E16 -> 7.196944 | G16: =IF(F16<-10,"ROBUST",IF(F16<0,"MARGINAL",IF(F16<15,"UNCERTAIN","UNFAVORABLE"))) -> UNCERTAIN | H16: =D16/C16 -> -47.711524
A17: CuV2O6 | B17: V2O5 | C17: 1 | D17: =Ternary_Rxns!N139 -> -44.98398 | E17: =C17*$C$10 -> 54.908469 | F17: =D17+E17 -> 9.9244887 | G17: =IF(F17<-10,"ROBUST",IF(F17<0,"MARGINAL",IF(F17<15,"UNCERTAIN","UNFAVORABLE"))) -> UNCERTAIN | H17: =D17/C17 -> -44.98398
A18: CuAl2O4 | B18: Al2O3 | C18: 1 | D18: =Ternary_Rxns!N24 -> -32.314512 | E18: =C18*$C$10 -> 54.908469 | F18: =D18+E18 -> 22.593956 | G18: =IF(F18<-10,"ROBUST",IF(F18<0,"MARGINAL",IF(F18<15,"UNCERTAIN","UNFAVORABLE"))) -> UNFAVORABLE | H18: =D18/C18 -> -32.314512
A19: Cu3V2O8 | B19: V2O5 | C19: 3 | D19: =Ternary_Rxns!N162 -> -109.15374 | E19: =C19*$C$10 -> 164.72541 | F19: =D19+E19 -> 55.571666 | G19: =IF(F19<-10,"ROBUST",IF(F19<0,"MARGINAL",IF(F19<15,"UNCERTAIN","UNFAVORABLE"))) -> UNFAVORABLE | H19: =D19/C19 -> -36.38458
A20: Cu2SiO4 | B20: SiO2 | C20: 2 | D20: =Ternary_Rxns!N231 -> -52.214204 | E20: =C20*$C$10 -> 109.81694 | F20: =D20+E20 -> 57.602733 | G20: =IF(F20<-10,"ROBUST",IF(F20<0,"MARGINAL",IF(F20<15,"UNCERTAIN","UNFAVORABLE"))) -> UNFAVORABLE | H20: =D20/C20 -> -26.107102
A22: γ_Cu SENSITIVITY ANALYSIS
A23: Change γ_Cu in cell C6 above to see all corrections update automatically.
A24: γ_Cu | B24: a_Cu | C24: Penalty/Cu (kJ) | D24: ΔG_eff CuFe2O4 | E24: ΔG_eff CuMn2O4 | F24: ΔG_eff CuB2O4 | G24: ΔG_eff CuV2O6 | H24: ΔG_eff CuAl2O4 | I24: ΔG_eff Cu3V2O8 | J24: ΔG_eff Cu2SiO4
A25: 3 | B25: =A25*$C$5 -> 0.009 | C25: =-$C$9*$C$8*LN(B25)/1000 -> 70.494034 | D25: =$D$14+$C$14*C25 -> -41.386268 | E25: =$D$15+$C$15*C25 -> 6.0514823 | F25: =$D$16+$C$16*C25 -> 22.78251 | G25: =$D$17+$C$17*C25 -> 25.510054 | H25: =$D$18+$C$18*C25 -> 38.179522 | I25: =$D$19+$C$19*C25 -> 102.32836 | J25: =$D$20+$C$20*C25 -> 88.773864
A26: 4 | B26: =A26*$C$5 -> 0.012 | C26: =-$C$9*$C$8*LN(B26)/1000 -> 66.188814 | D26: =$D$14+$C$14*C26 -> -45.691487 | E26: =$D$15+$C$15*C26 -> 1.7462625 | F26: =$D$16+$C$16*C26 -> 18.47729 | G26: =$D$17+$C$17*C26 -> 21.204834 | H26: =$D$18+$C$18*C26 -> 33.874302 | I26: =$D$19+$C$19*C26 -> 89.412703 | J26: =$D$20+$C$20*C26 -> 80.163425
A27: 5 | B27: =A27*$C$5 -> 0.015 | C27: =-$C$9*$C$8*LN(B27)/1000 -> 62.849426 | D27: =$D$14+$C$14*C27 -> -49.030875 | E27: =$D$15+$C$15*C27 -> -1.5931253 | F27: =$D$16+$C$16*C27 -> 15.137902 | G27: =$D$17+$C$17*C27 -> 17.865447 | H27: =$D$18+$C$18*C27 -> 30.534914 | I27: =$D$19+$C$19*C27 -> 79.39454 | J27: =$D$20+$C$20*C27 -> 73.484649
A28: 6 | B28: =A28*$C$5 -> 0.018 | C28: =-$C$9*$C$8*LN(B28)/1000 -> 60.120948 | D28: =$D$14+$C$14*C28 -> -51.759354 | E28: =$D$15+$C$15*C28 -> -4.3216039 | F28: =$D$16+$C$16*C28 -> 12.409423 | G28: =$D$17+$C$17*C28 -> 15.136968 | H28: =$D$18+$C$18*C28 -> 27.806436 | I28: =$D$19+$C$19*C28 -> 71.209104 | J28: =$D$20+$C$20*C28 -> 68.027692
A29: 7 | B29: =A29*$C$5 -> 0.021 | C29: =-$C$9*$C$8*LN(B29)/1000 -> 57.814052 | D29: =$D$14+$C$14*C29 -> -54.066249 | E29: =$D$15+$C$15*C29 -> -6.6284997 | F29: =$D$16+$C$16*C29 -> 10.102528 | G29: =$D$17+$C$17*C29 -> 12.830072 | H29: =$D$18+$C$18*C29 -> 25.49954 | I29: =$D$19+$C$19*C29 -> 64.288417 | J29: =$D$20+$C$20*C29 -> 63.4139
A30: 8 | B30: =A30*$C$5 -> 0.024 | C30: =-$C$9*$C$8*LN(B30)/1000 -> 55.815728 | D30: =$D$14+$C$14*C30 -> -56.064573 | E30: =$D$15+$C$15*C30 -> -8.6268237 | F30: =$D$16+$C$16*C30 -> 8.1042036 | G30: =$D$17+$C$17*C30 -> 10.831748 | H30: =$D$18+$C$18*C30 -> 23.501216 | I30: =$D$19+$C$19*C30 -> 58.293445 | J30: =$D$20+$C$20*C30 -> 59.417252
A31: 8.5 | B31: =A31*$C$5 -> 0.0255 | C31: =-$C$9*$C$8*LN(B31)/1000 -> 54.908469 | D31: =$D$14+$C$14*C31 -> -56.971833 | E31: =$D$15+$C$15*C31 -> -9.5340833 | F31: =$D$16+$C$16*C31 -> 7.196944 | G31: =$D$17+$C$17*C31 -> 9.9244887 | H31: =$D$18+$C$18*C31 -> 22.593956 | I31: =$D$19+$C$19*C31 -> 55.571666 | J31: =$D$20+$C$20*C31 -> 57.602733
A32: 9 | B32: =A32*$C$5 -> 0.027 | C32: =-$C$9*$C$8*LN(B32)/1000 -> 54.053081 | D32: =$D$14+$C$14*C32 -> -57.82722 | E32: =$D$15+$C$15*C32 -> -10.38947 | F32: =$D$16+$C$16*C32 -> 6.3415569 | G32: =$D$17+$C$17*C32 -> 9.0691016 | H32: =$D$18+$C$18*C32 -> 21.738569 | I32: =$D$19+$C$19*C32 -> 53.005505 | J32: =$D$20+$C$20*C32 -> 55.891959
A33: 10 | B33: =A33*$C$5 -> 0.03 | C33: =-$C$9*$C$8*LN(B33)/1000 -> 52.47634 | D33: =$D$14+$C$14*C33 -> -59.403961 | E33: =$D$15+$C$15*C33 -> -11.966212 | F33: =$D$16+$C$16*C33 -> 4.7648158 | G33: =$D$17+$C$17*C33 -> 7.4923604 | H33: =$D$18+$C$18*C33 -> 20.161828 | I33: =$D$19+$C$19*C33 -> 48.275281 | J33: =$D$20+$C$20*C33 -> 52.738477
A34: 11 | B34: =A34*$C$5 -> 0.033 | C34: =-$C$9*$C$8*LN(B34)/1000 -> 51.050004 | D34: =$D$14+$C$14*C34 -> -60.830297 | E34: =$D$15+$C$15*C34 -> -13.392547 | F34: =$D$16+$C$16*C34 -> 3.3384799 | G34: =$D$17+$C$17*C34 -> 6.0660245 | H34: =$D$18+$C$18*C34 -> 18.735492 | I34: =$D$19+$C$19*C34 -> 43.996273 | J34: =$D$20+$C$20*C34 -> 49.885805
A35: 12 | B35: =A35*$C$5 -> 0.036 | C35: =-$C$9*$C$8*LN(B35)/1000 -> 49.747862 | D35: =$D$14+$C$14*C35 -> -62.13244 | E35: =$D$15+$C$15*C35 -> -14.69469 | F35: =$D$16+$C$16*C35 -> 2.0363372 | G35: =$D$17+$C$17*C35 -> 4.7638819 | H35: =$D$18+$C$18*C35 -> 17.43335 | I35: =$D$19+$C$19*C35 -> 40.089846 | J35: =$D$20+$C$20*C35 -> 47.28152
A36: 13 | B36: =A36*$C$5 -> 0.039 | C36: =-$C$9*$C$8*LN(B36)/1000 -> 48.550007 | D36: =$D$14+$C$14*C36 -> -63.330295 | E36: =$D$15+$C$15*C36 -> -15.892545 | F36: =$D$16+$C$16*C36 -> 0.83848206 | G36: =$D$17+$C$17*C36 -> 3.5660267 | H36: =$D$18+$C$18*C36 -> 16.235494 | I36: =$D$19+$C$19*C36 -> 36.49628 | J36: =$D$20+$C$20*C36 -> 44.885809
A37: 15 | B37: =A37*$C$5 -> 0.045 | C37: =-$C$9*$C$8*LN(B37)/1000 -> 46.408474 | D37: =$D$14+$C$14*C37 -> -65.471828 | E37: =$D$15+$C$15*C37 -> -18.034078 | F37: =$D$16+$C$16*C37 -> -1.3030507 | G37: =$D$17+$C$17*C37 -> 1.424494 | H37: =$D$18+$C$18*C37 -> 14.093962 | I37: =$D$19+$C$19*C37 -> 30.071682 | J37: =$D$20+$C$20*C37 -> 40.602744
A67: SLAG COMPOSITION EFFECTS ON Cu ACTIVITY
A68: System | B68: Ratio Label | C68: Ratio Value | D68: a_Cu | E68: % Change from Baseline
A69: =Slag_Effects!A4 -> Cu-Mn-Si-O | B69: =Slag_Effects!B4 -> MnO:SiO2 | C69: =Slag_Effects!C4 -> 0.2 | D69: =Slag_Effects!I4 -> 0.00060242872 | E69: 0
A70: =Slag_Effects!A5 -> Cu-Mn-Si-O | B70: =Slag_Effects!B5 -> MnO:SiO2 | C70: =Slag_Effects!C5 -> 0.4 | D70: =Slag_Effects!I5 -> 0.00059216467 | E70: =(D70-D$69)/D$69*100 -> -1.7037785
A71: =Slag_Effects!A6 -> Cu-Mn-Si-O | B71: =Slag_Effects!B6 -> MnO:SiO2 | C71: =Slag_Effects!C6 -> 0.6 | D71: =Slag_Effects!I6 -> 0.00058498596 | E71: =(D71-D$69)/D$69*100 -> -2.8954061
A72: =Slag_Effects!A7 -> Cu-Mn-Si-O | B72: =Slag_Effects!B7 -> MnO:SiO2 | C72: =Slag_Effects!C7 -> 0.8 | D72: =Slag_Effects!I7 -> 0.00057955787 | E72: =(D72-D$69)/D$69*100 -> -3.7964406
...

Sheet Normalization
A1: NORMALIZATION — How TC-Python GM values become ΔGᶠ (kJ/mol O₂)
A2: Section 1: Binary oxide stoichiometry (17 oxides). Section 2: Ternary product stoichiometry (18 products). Sections 3-4: Worked examples with traceable formulas.
A4: SECTION 1: BINARY OXIDE NORMALIZATION
A5: TC-Python reports GM = Gibbs energy per mole of ATOMS. Pipeline: GM × atoms/formula → G(oxide); then ΔGᶠ = G(oxide) − G(metals) − G(O₂); finally ΔGᶠ / n_O₂ → kJ/mol O₂ for Ellingham comparison.
A7: Oxide | B7: Atoms/Formula | C7: Balanced Reaction | D7: oxide/O₂ | E7: GM @ 1800 K (J/mol-at) | F7: ΔG per mol O₂ (kJ)
A8: Cu2O | B8: 3 | C8: 4Cu + O2 -> 2Cu2O | D8: 2 | E8: =OX_Gibbs!C30 -> -159013.89 | F8: =OX_Gibbs!F30/1000 -> -87.468853
A9: Al2O3 | B9: 5 | C9: 4/3 Al + O2 -> 2/3 Al2O3 | D9: 0.667 | E9: =OX_Gibbs!O30 -> -391060.11 | F9: =OX_Gibbs!R30/1000 -> -732.29108
A10: MgO | B10: 2 | C10: 2Mg + O2 -> 2MgO | D10: 2 | E10: =OX_Gibbs!U30 -> -365091.54 | F10: =OX_Gibbs!X30/1000 -> -730.33088
A11: SiO2 | B11: 3 | C11: Si + O2 -> SiO2 | D11: 1 | E11: =OX_Gibbs!AA30 -> -364560.11 | F11: =OX_Gibbs!AD30/1000 -> -590.18934
A12: TiO2 | B12: 3 | C12: Ti + O2 -> TiO2 | D12: 1 | E12: =OX_Gibbs!AG30 -> -383762.58 | F12: =OX_Gibbs!AJ30/1000 -> -618.76705
A13: FeO | B13: 2 | C13: 2Fe + O2 -> 2FeO | D13: 2 | E13: =OX_Gibbs!AM30 -> -235131.74 | F13: =OX_Gibbs!AP30/1000 -> -301.27684
A14: CaO | B14: 2 | C14: 2Ca + O2 -> 2CaO | D14: 2 | E14: =OX_Gibbs!AS30 -> -394797.26 | F14: =OX_Gibbs!AV30/1000 -> -878.77799
A15: ZrO2 | B15: 3 | C15: Zr + O2 -> ZrO2 | D15: 1 | E15: =OX_Gibbs!AY30 -> -437021.95 | F15: =OX_Gibbs!BB30/1000 -> -763.16813
A16: Cr2O3 | B16: 5 | C16: 4/3 Cr + O2 -> 2/3 Cr2O3 | D16: 0.667 | E16: =OX_Gibbs!BE30 -> -296471.24 | F16: =OX_Gibbs!BH30/1000 -> -442.30782
A17: MnO | B17: 2 | C17: 2Mn + O2 -> 2MnO | D17: 2 | E17: =OX_Gibbs!BK30 -> -289975.68 | F17: =OX_Gibbs!BN30/1000 -> -496.36288
A18: V2O5 | B18: 7 | C18: 4/5 V + O2 -> 2/5 V2O5 | D18: 0.4 | E18: =OX_Gibbs!CO30 -> -305109.32 | F18: =OX_Gibbs!CR30/1000 -> -346.88653
A19: B2O3 | B19: 5 | C19: 4/3 B + O2 -> 2/3 B2O3 | D19: 0.667 | E19: =OX_Gibbs!CI30 -> -315909.82 | F19: =OX_Gibbs!CL30/1000 -> -568.57302
A20: La2O3 | B20: 5 | C20: 4/3 La + O2 -> 2/3 La2O3 | D20: 0.667 | E20: =OX_Gibbs!CU30 -> -447180.62 | F20: =OX_Gibbs!CX30/1000 -> -853.74793
A21: CeO2 | B21: 3 | C21: Ce + O2 -> CeO2 | D21: 1 | E21: =OX_Gibbs!DA30 -> 0 | F21: =OX_Gibbs!DD30/1000 -> -1328.1808
A22: NiO | B22: 2 | C22: 2Ni + O2 -> 2NiO | D22: 2 | E22: =OX_Gibbs!BQ30 -> -200868.58 | F22: =OX_Gibbs!BT30/1000 -> -163.49179
A23: CoO | B23: 2 | C23: 2Co + O2 -> 2CoO | D23: 2 | E23: =OX_Gibbs!BW30 -> -214124.99 | F23: =OX_Gibbs!BZ30/1000 -> -214.08761
A24: PbO | B24: 2 | C24: 2Pb + O2 -> 2PbO | D24: 2 | E24: =OX_Gibbs!CC30 -> 0 | F24: =OX_Gibbs!CF30/1000 -> -223.62415
A26: SECTION 2: TERNARY PRODUCT STOICHIOMETRY
A27: Ternary reaction: Cu + MOₓ + O₂ → CuMOᵧ. If ΔG < 0 the oxide captures copper into a ternary compound (or slag dissolution at steelmaking T).
A29: Product | B29: Name | C29: Reaction | D29: Parent Oxide | E29: n_Cu | F29: n_oxide | G29: n_O₂ | H29: Product Atoms | I29: Category
A30: CuAl2O4 | B30: Cu aluminate spinel | C30: Cu + Al2O3 + 0.5O2 -> CuAl2O4 | D30: Al2O3 | E30: 1 | F30: 1 | G30: 0.5 | H30: 7 | I30: Spinel
A31: CuAlO2 | B31: Delafossite | C31: Cu + 0.5Al2O3 + 0.25O2 -> CuAlO2 | D31: Al2O3 | E31: 1 | F31: 0.5 | G31: 0.25 | H31: 4 | I31: Delafossite
A32: CuCr2O4 | B32: Cu chromite spinel | C32: Cu + Cr2O3 + 0.5O2 -> CuCr2O4 | D32: Cr2O3 | E32: 1 | F32: 1 | G32: 0.5 | H32: 7 | I32: Spinel
A33: CuMn2O4 | B33: Cu manganite spinel | C33: Cu + 2MnO + O2 -> CuMn2O4 | D33: MnO | E33: 1 | F33: 2 | G33: 1 | H33: 7 | I33: Spinel
A34: CuFe2O4 | B34: Cu ferrite spinel | C34: Cu + 2FeO + O2 -> CuFe2O4 | D34: FeO | E34: 1 | F34: 2 | G34: 1 | H34: 7 | I34: Spinel
A35: CuCo2O4 | B35: Cu cobaltite spinel | C35: Cu + 2CoO + O2 -> CuCo2O4 | D35: CoO | E35: 1 | F35: 2 | G35: 1 | H35: 7 | I35: Spinel
A36: CuV2O6 | B36: Copper vanadate | C36: Cu + V2O5 + 0.5O2 -> CuV2O6 | D36: V2O5 | E36: 1 | F36: 1 | G36: 0.5 | H36: 9 | I36: Vanadate
A37: Cu3V2O8 | B37: Cu orthovanadate | C37: 3Cu + V2O5 + 1.5O2 -> Cu3V2O8 | D37: V2O5 | E37: 3 | F37: 1 | G37: 1.5 | H37: 13 | I37: Vanadate
A38: CuTiO3 | B38: Copper titanate | C38: Cu + TiO2 + 0.5O2 -> CuTiO3 | D38: TiO2 | E38: 1 | F38: 1 | G38: 0.5 | H38: 5 | I38: Titanate
A39: CuSiO3 | B39: Cu metasilicate | C39: Cu + SiO2 + 0.5O2 -> CuSiO3 | D39: SiO2 | E39: 1 | F39: 1 | G39: 0.5 | H39: 5 | I39: Silicate
A40: Cu2SiO4 | B40: Cu orthosilicate | C40: 2Cu + SiO2 + O2 -> Cu2SiO4 | D40: SiO2 | E40: 2 | F40: 1 | G40: 1 | H40: 7 | I40: Silicate
A41: CuMgO2 | B41: Cu magnesioxide (hyp) | C41: Cu + MgO + 0.5O2 -> CuMgO2 | D41: MgO | E41: 1 | F41: 1 | G41: 0.5 | H41: 4 | I41: Hypothetical
... A47: CuB2O4 | B47: Copper borate | C47: Cu + B2O3 + 0.5O2 -> CuB2O4 | D47: B2O3 | E47: 1 | F47: 1 | G47: 0.5 | H47: 7 | I47: Borate
A49: SECTION 3: WORKED EXAMPLE — Al₂O₃ (corundum)
A50: 2Al + 1.5 O₂ → Al₂O₃. Every cell traces to OX_Gibbs or CuFe2O4_Raw.
...

Sheet Screening_Table
A1: BINARY SCREENING TABLE — One row per candidate oxide
A2: ΔG_rxn from TC-Python TCOX14 at three temperatures. Column K = toxicity hazard. RED = HIGH hazard — additional safety review required before experimental use.
A3: Oxide | B3: Formula | C3: Density (g/cm³) | D3: Melting Point (°C) | E3: Floats on Steel? | F3: Solid at 1527°C? | G3: ΔG_rxn @ 727°C (kJ/mol O₂) | H3: ΔG_rxn @ 1227°C (kJ/mol O₂) | I3: ΔG_rxn @ 1527°C (kJ/mol O₂) | J3: Cu Can Reduce? | K3: Toxicity | L3: Cost / Availability
A4: MgO | B4: MgO | C4: 3.58 | D4: 2852 | E4: Yes | F4: Yes | G4: 796 | H4: 736.5 | I4: 642.9 | J4: No | K4: Low | L4: $0.0003/g
A5: Al₂O₃ | B5: Al2O3 | C5: 3.95 | D5: 2072 | E5: Yes | F5: Yes | G5: 716.7 | H5: 682.7 | I5: 644.8 | J5: No | K5: Low | L5: $0.0005/g
A6: CaO | B6: CaO | C6: 3.34 | D6: 2613 | E6: Yes | F6: Yes | G6: 870.2 | H6: 836.4 | I6: 791.3 | J6: No | K6: Low | L6: $0.0002/g
A7: ZrO₂ | B7: ZrO2 | C7: 5.68 | D7: 2715 | E7: Yes | F7: Yes | G7: 718.6 | H7: 702.1 | I7: 675.7 | J7: No | K7: Low | L7: $0.035/g
A8: Cr₂O₃ | B8: Cr2O3 | C8: 5.22 | D8: 2435 | E8: Yes | F8: Yes | G8: 385.7 | H8: 377.8 | I8: 354.8 | J8: No | K8: Moderate — Cr(VI) risk if oxidized | L8: $0.005/g
A9: TiO₂ | B9: TiO2 | C9: 4.23 | D9: 1843 | E9: Yes | F9: Yes | G9: 569.4 | H9: 556.7 | I9: 531.3 | J9: No | K9: Low | L9: $0.003/g
A10: SiO₂ | B10: SiO2 | C10: 2.65 | D10: 1713 | E10: Yes | F10: Yes | G10: 539.4 | H10: 529.4 | I10: 502.7 | J10: No | K10: Low (crystalline = inhalation hazard) | L10: $0.00005/g
A11: MnO | B11: MnO | C11: 5.43 | D11: 1842 | E11: Yes | F11: Yes | G11: 434.1 | H11: 433.9 | I11: 408.9 | J11: No | K11: Low | L11: $0.005/g
A12: FeO | B12: FeO | C12: 5.74 | D12: 1377 | E12: Yes | F12: No — LIQUID | G12: 220.4 | H12: 230.7 | I12: 213.8 | J12: No | K12: Low | L12: $0.0009/g
A13: CuO | B13: CuO | C13: 6.31 | D13: 1326 | E13: Yes | F13: No — LIQUID | G13: -58.8 | H13: -51.7 | I13: -41 | J13: Trivially yes (Cu self-oxidation) | K13: Moderate — aquatic toxin | L13: $0.008/g
A14: NiO | B14: NiO | C14: 6.67 | D14: 1955 | E14: Yes | F14: Yes | G14: 107.5 | H14: 99.5 | I14: 76 | J14: No | K14: HIGH — IARC Group 1 carcinogen (inhalation) | L14: $0.016/g
A15: CoO | B15: CoO | C15: 6.44 | D15: 1830 | E15: Yes | F15: Yes | G15: 134.9 | H15: 141.3 | I15: 126.6 | J15: No | K15: HIGH — Carc. 1B, reproductive toxin | L15: $0.018/g
A16: PbO | B16: PbO | C16: 9.53 | D16: 888 | E16: No | F16: No — LIQUID | G16: -34.7 | H16: 81 | I16: 136.2 | J16: No | K16: HIGH — Repr. 1A, cumulative neurotoxin | L16: $0.004/g
A17: B₂O₃ | B17: B2O3 | C17: 2.55 | D17: 450 | E17: Yes | F17: No — LIQUID | G17: No data at this T | H17: No data at this T | I17: 481.1 | J17: No | K17: Moderate — Repr. 1B reproductive toxicant | L17: $0.003/g
A18: V₂O₅ | B18: V2O5 | C18: 3.36 | D18: 690 | E18: Yes | F18: No — LIQUID | G18: 257.2 | H18: 267 | I18: 259.4 | J18: No | K18: HIGH — Carc. 1B, mutagenic, acute toxic | L18: $0.011/g
A19: La₂O₃ | B19: La2O3 | C19: 6.51 | D19: 2315 | E19: Yes | F19: Yes | G19: 813 | H19: 795.2 | I19: 766.3 | J19: No | K19: Low-Moderate — mild pulmonary risk | L19: $0.010/g
A20: CeO₂ | B20: CeO2 | C20: 7.22 | D20: 2400 | E20: No | F20: Yes | G20: 997.2 | H20: 1156.3 | I20: 1240.7 | J20: No | K20: Low | L20: $0.006/g

Sheet Ternary_Verdicts
A1: TERNARY VERDICTS — One row per Cu-M-O product
A2: ΔG < 0 means oxide captures Cu into a ternary compound. Col I shows equilibrium phases at 1527°C (all melt into IONIC_LIQ at steelmaking temp).
A3: Product | B3: Name | C3: Oxide | D3: Reaction | E3: dG_rxn @ 727°C (kJ) | F3: dG_rxn @ 1227°C (kJ) | G3: dG_rxn @ 1527°C (kJ) | H3: Ternary Phase Found | I3: Stable Phases @ 1527°C | J3: Verdict
A4: CuAl2O4 | B4: copper aluminate spinel | C4: Al2O3 | D4: Cu + Al2O3 + 0.5 O2 -> CuAl2O4 | E4: -72.7 | F4: -38.8 | G4: -32.3 | H4: SPINEL#1 (to 1550 K) | I4: CORUNDUM#1; GAS#1; IONIC_LIQ#2 | J4: FAVORABLE — Cu captured
A5: CuAlO2 | B5: delafossite | C5: Al2O3 | D5: Cu + 0.5 Al2O3 + 0.25 O2 -> CuAlO2 | E5: -52.5 | F5: -35 | G5: -30.1 | H5: SPINEL#1 (to 1550 K) | I5: CORUNDUM#1; IONIC_LIQ#1; IONIC_LIQ#2 | J5: FAVORABLE — Cu captured
A6: CuCr2O4 | B6: copper chromite spinel | C6: Cr2O3 | D6: Cu + Cr2O3 + 0.5 O2 -> CuCr2O4 | E6: -82.3 | F6: -43.7 | G6: -30 | H6: ALPHA_SPINEL#1 (to 1900 K) | I6: CORUNDUM#1; DELAFOSSITE#1; GAS#1 | J6: FAVORABLE — Cu captured
A7: CuMn2O4 | B7: copper manganite spinel | C7: MnO | D7: Cu + 2MnO + O2 -> CuMn2O4 | E7: -161.8 | F7: -79.2 | G7: -64.4 | H7: SPINEL#1 (to 1700 K) | I7: GAS#1; IONIC_LIQ#2 | J7: FAVORABLE — Cu captured
A8: CuFe2O4 | B8: copper ferrite spinel | C8: FeO | D8: Cu + 2FeO + O2 -> CuFe2O4 | E8: -235.7 | F8: -149.6 | G8: -111.9 | H8: SPINEL#1 (to 1700 K) | I8: GAS#1; IONIC_LIQ#2 | J8: FAVORABLE — Cu captured
A9: CuV2O6 | B9: copper vanadate | C9: V2O5 | D9: Cu + V2O5 + 0.5 O2 -> CuV2O6 | E9: -66.7 | F9: -49.5 | G9: -45 | H9: none (liquid at all T) | I9: GAS#1; IONIC_LIQ#2 | J9: FAVORABLE — Cu captured
A10: Cu3V2O8 | B10: copper orthovanadate | C10: V2O5 | D10: 3Cu + V2O5 + 1.5 O2 -> Cu3V2O8 | E10: -198.7 | F10: -127.1 | G10: -109.2 | H10: none (liquid at all T) | I10: GAS#1; IONIC_LIQ#2 | J10: FAVORABLE — Cu captured
A11: CuTiO3 | B11: copper titanate | C11: TiO2 | D11: Cu + TiO2 + 0.5 O2 -> CuTiO3 | E11: -66.2 | F11: -37.3 | G11: -36.8 | H11: none (liquid at all T) | I11: GAS#1; IONIC_LIQ#2 | J11: FAVORABLE — Cu captured
A12: CuSiO3 | B12: copper metasilicate | C12: SiO2 | D12: Cu + SiO2 + 0.5 O2 -> CuSiO3 | E12: -66.2 | F12: -32.9 | G12: -26.2 | H12: none (liquid at all T) | I12: CRISTOBALITE#1; GAS#1; IONIC_LIQ#2 | J12: FAVORABLE — Cu captured
A13: Cu2SiO4 | B13: copper orthosilicate | C13: SiO2 | D13: 2Cu + SiO2 + O2 -> Cu2SiO4 | E13: -132.2 | F13: -65.7 | G13: -52.2 | H13: none (liquid at all T) | I13: CRISTOBALITE#1; GAS#1; IONIC_LIQ#2 | J13: FAVORABLE — Cu captured
A14: CuMgO2 | B14: copper magnesioxide (hypothetical) | C14: MgO | D14: Cu + MgO + 0.5 O2 -> CuMgO2 | E14: -67.9 | F14: -33.9 | G14: -26.1 | H14: GUGGENITE#1 (to 1350 K) | I14: GAS#1; HALITE#1; IONIC_LIQ#2 | J14: FAVORABLE — Cu captured
A15: CuCaO2 | B15: copper calcioxide (hypothetical) | C15: CaO | D15: Cu + CaO + 0.5 O2 -> CuCaO2 | E15: -67.3 | F15: -36.6 | G15: -30.7 | H15: CA2CUO3#1 (to 1300 K) | I15: GAS#1; HALITE#1; IONIC_LIQ#2 | J15: FAVORABLE — Cu captured
... A19: CuLaO2 | B19: copper lanthanum oxide | C19: La2O3 | D19: Cu + 0.5 La2O3 + 0.25 O2 -> CuLaO2 | E19: -50.9 | F19: -31.1 | G19: -27.8 | H19: DELAFOSSITE#1 (to 1500 K) | I19: IONIC_LIQ#1; IONIC_LIQ#2; M2O3A#1 | J19: FAVORABLE — Cu captured
A20: CuCeO3 | B20: copper cerate (hypothetical) | C20: CeO2 | D20: Cu + CeO2 + 0.5 O2 -> CuCeO3 | E20: No data | F20: No data | G20: No data | H20: none (liquid at all T) | I20: ERROR: Thermo-Calc calculation error: se.thermocalc.core.CalculationEngineException: The element CE is not in the database, it contains only the following elements: [/-, AL, AR, B, BA, C, CA, CO, CR, CU, F, FE, GD, H, HF, K, LA, LI, MG, MN, MO, N, NA, NB, NI, O, P, S, SI, TI, V, VA, W, Y, YB, ZR] | J20: No data
A21: CuB2O4 | B21: copper borate | C21: B2O3 | D21: Cu + B2O3 + 0.5 O2 -> CuB2O4 | E21: -79.7 | F21: -51.3 | G21: -47.7 | H21: CUB2O4#1 (to 1300 K) | I21: GAS#1; IONIC_LIQ#2 | J21: FAVORABLE — Cu captured

Sheet Activity_Corrected
A1: ACTIVITY-CORRECTED ΔG — Accounting for dilute Cu in liquid Fe
A2: Pre-computed at X_Cu=0.003, γ_Cu=8.5. Column M verdict is a live formula. See Activity_and_Slag tab for interactive version with editable parameter cells.
A3: product | B3: parent_oxide | C3: T_K | D3: T_C | E3: dG_pure_kJ | F3: Cu_correction_kJ | G3: O2_correction_air_kJ | H3: dG_corrected_pO2_1atm_kJ | I3: dG_corrected_pO2_air_kJ | J3: a_Cu | K3: n_Cu | L3: n_O2 | M3: verdict_corrected
A4: CuFe2O4 | B4: FeO | C4: 800 | D4: 526.85 | E4: -271.03 | F4: 24.4 | G4: 10.38 | H4: -246.63 | I4: -236.25 | J4: 0.0255 | K4: 1 | L4: 1 | M4: =IF(H4<-10,"ROBUST",IF(H4<0,"MARGINAL",IF(H4<15,"UNCERTAIN","UNFAVORABLE"))) -> ROBUST
A5: CuFe2O4 | B5: FeO | C5: 825 | D5: 551.85 | E5: -267.09 | F5: 25.17 | G5: 10.7 | H5: -241.93 | I5: -231.22 | J5: 0.0255 | K5: 1 | L5: 1 | M5: =IF(H5<-10,"ROBUST",IF(H5<0,"MARGINAL",IF(H5<15,"UNCERTAIN","UNFAVORABLE"))) -> ROBUST
A6: CuFe2O4 | B6: FeO | C6: 850 | D6: 576.85 | E6: -262.71 | F6: 25.93 | G6: 11.03 | H6: -236.79 | I6: -225.76 | J6: 0.0255 | K6: 1 | L6: 1 | M6: =IF(H6<-10,"ROBUST",IF(H6<0,"MARGINAL",IF(H6<15,"UNCERTAIN","UNFAVORABLE"))) -> ROBUST
A7: CuFe2O4 | B7: FeO | C7: 875 | D7: 601.85 | E7: -258.17 | F7: 26.69 | G7: 11.35 | H7: -231.48 | I7: -220.12 | J7: 0.0255 | K7: 1 | L7: 1 | M7: =IF(H7<-10,"ROBUST",IF(H7<0,"MARGINAL",IF(H7<15,"UNCERTAIN","UNFAVORABLE"))) -> ROBUST
A8: CuFe2O4 | B8: FeO | C8: 900 | D8: 626.85 | E8: -253.64 | F8: 27.45 | G8: 11.68 | H8: -226.18 | I8: -214.51 | J8: 0.0255 | K8: 1 | L8: 1 | M8: =IF(H8<-10,"ROBUST",IF(H8<0,"MARGINAL",IF(H8<15,"UNCERTAIN","UNFAVORABLE"))) -> ROBUST
A9: CuFe2O4 | B9: FeO | C9: 925 | D9: 651.85 | E9: -249.13 | F9: 28.22 | G9: 12 | H9: -220.91 | I9: -208.91 | J9: 0.0255 | K9: 1 | L9: 1 | M9: =IF(H9<-10,"ROBUST",IF(H9<0,"MARGINAL",IF(H9<15,"UNCERTAIN","UNFAVORABLE"))) -> ROBUST
A10: CuFe2O4 | B10: FeO | C10: 950 | D10: 676.85 | E10: -244.63 | F10: 28.98 | G10: 12.33 | H10: -215.65 | I10: -203.33 | J10: 0.0255 | K10: 1 | L10: 1 | M10: =IF(H10<-10,"ROBUST",IF(H10<0,"MARGINAL",IF(H10<15,"UNCERTAIN","UNFAVORABLE"))) -> ROBUST
A11: CuFe2O4 | B11: FeO | C11: 975 | D11: 701.85 | E11: -240.16 | F11: 29.74 | G11: 12.65 | H11: -210.41 | I11: -197.76 | J11: 0.0255 | K11: 1 | L11: 1 | M11: =IF(H11<-10,"ROBUST",IF(H11<0,"MARGINAL",IF(H11<15,"UNCERTAIN","UNFAVORABLE"))) -> ROBUST
A12: CuFe2O4 | B12: FeO | C12: 1000 | D12: 726.85 | E12: -235.69 | F12: 30.5 | G12: 12.98 | H12: -205.19 | I12: -192.21 | J12: 0.0255 | K12: 1 | L12: 1 | M12: =IF(H12<-10,"ROBUST",IF(H12<0,"MARGINAL",IF(H12<15,"UNCERTAIN","UNFAVORABLE"))) -> ROBUST
A13: CuFe2O4 | B13: FeO | C13: 1025 | D13: 751.85 | E13: -231.25 | F13: 31.27 | G13: 13.3 | H13: -199.98 | I13: -186.68 | J13: 0.0255 | K13: 1 | L13: 1 | M13: =IF(H13<-10,"ROBUST",IF(H13<0,"MARGINAL",IF(H13<15,"UNCERTAIN","UNFAVORABLE"))) -> ROBUST
A14: CuFe2O4 | B14: FeO | C14: 1050 | D14: 776.85 | E14: -226.81 | F14: 32.03 | G14: 13.62 | H14: -194.78 | I14: -181.16 | J14: 0.0255 | K14: 1 | L14: 1 | M14: =IF(H14<-10,"ROBUST",IF(H14<0,"MARGINAL",IF(H14<15,"UNCERTAIN","UNFAVORABLE"))) -> ROBUST
A15: CuFe2O4 | B15: FeO | C15: 1075 | D15: 801.85 | E15: -222.39 | F15: 32.79 | G15: 13.95 | H15: -189.6 | I15: -175.65 | J15: 0.0255 | K15: 1 | L15: 1 | M15: =IF(H15<-10,"ROBUST",IF(H15<0,"MARGINAL",IF(H15<15,"UNCERTAIN","UNFAVORABLE"))) -> ROBUST
... A288: Cu2SiO4 | B288: SiO2 | C288: 1900 | D288: 1626.85 | E288: -48.26 | F288: 115.92 | G288: 24.65 | H288: 67.65 | I288: 92.31 | J288: 0.0255 | K288: 2 | L288: 1 | M288: =IF(H288<-10,"ROBUST",IF(H288<0,"MARGINAL",IF(H288<15,"UNCERTAIN","UNFAVORABLE"))) -> UNFAVORABLE

Sheet OX_Gibbs
A1: RAW TC-PYTHON — Binary oxide Gibbs energies (18 oxides, TCOX14+SSUB3)
A2: GM values are per mole of ATOMS. See Normalization tab for conversion to kJ/mol O₂. Temperatures: 500-2000 K in 50 K steps.
A3: T_K | B3: T_C | C3: GM_Cu2O | D3: GM_system_Cu2O | E3: G_metal_Cu2O | F3: dG_Cu2O_per_O2 | G3: phases_Cu2O | H3: oxide_phase_Cu2O | I3: GM_CuO | J3: GM_system_CuO | K3: G_metal_CuO | L3: dG_CuO_per_O2 | M3: phases_CuO | N3: oxide_phase_CuO | O3: GM_Al2O3 | P3: GM_system_Al2O3 | Q3: G_metal_Al2O3 | R3: dG_Al2O3_per_O2 | S3: phases_Al2O3 | T3: oxide_phase_Al2O3 | U3: GM_MgO | V3: GM_system_MgO | W3: G_metal_MgO | X3: dG_MgO_per_O2 | Y3: phases_MgO | Z3: oxide_phase_MgO | AA3: GM_SiO2 | AB3: GM_system_SiO2 | AC3: G_metal_SiO2 | AD3: dG_SiO2_per_O2 | AE3: phases_SiO2 | AF3: oxide_phase_SiO2 | AG3: GM_TiO2 | AH3: GM_system_TiO2 | AI3: G_metal_TiO2 | AJ3: dG_TiO2_per_O2 | AK3: phases_TiO2 | AL3: oxide_phase_TiO2 | AM3: GM_FeO | AN3: GM_system_FeO | AO3: G_metal_FeO | AP3: dG_FeO_per_O2 | AQ3: phases_FeO | AR3: oxide_phase_FeO | AS3: GM_CaO | AT3: GM_system_CaO | AU3: G_metal_CaO | AV3: dG_CaO_per_O2 | AW3: phases_CaO | AX3: oxide_phase_CaO | AY3: GM_ZrO2 | AZ3: GM_system_ZrO2 | BA3: G_metal_ZrO2 | BB3: dG_ZrO2_per_O2 | BC3: phases_ZrO2 | BD3: oxide_phase_ZrO2 | BE3: GM_Cr2O3 | BF3: GM_system_Cr2O3 | BG3: G_metal_Cr2O3 | BH3: dG_Cr2O3_per_O2 | BI3: phases_Cr2O3 | BJ3: oxide_phase_Cr2O3 | BK3: GM_MnO | BL3: GM_system_MnO | BM3: G_metal_MnO | BN3: dG_MnO_per_O2 | BO3: phases_MnO | BP3: oxide_phase_MnO | BQ3: GM_NiO | BR3: GM_system_NiO | BS3: G_metal_NiO | BT3: dG_NiO_per_O2 | BU3: phases_NiO | BV3: oxide_phase_NiO | BW3: GM_CoO | BX3: GM_system_CoO | BY3: G_metal_CoO | BZ3: dG_CoO_per_O2 | CA3: phases_CoO | CB3: oxide_phase_CoO | CC3: GM_PbO | CD3: GM_system_PbO | CE3: G_metal_PbO | CF3: dG_PbO_per_O2 | CG3: phases_PbO | CH3: oxide_phase_PbO | CI3: GM_B2O3 | CJ3: GM_system_B2O3 | CK3: G_metal_B2O3 | CL3: dG_B2O3_per_O2 | CM3: phases_B2O3 | CN3: oxide_phase_B2O3 | CO3: GM_V2O5 | CP3: GM_system_V2O5 | CQ3: G_metal_V2O5 | CR3: dG_V2O5_per_O2 | CS3: phases_V2O5 | CT3: oxide_phase_V2O5 | CU3: GM_La2O3 | CV3: GM_system_La2O3 | CW3: G_metal_La2O3 | CX3: dG_La2O3_per_O2 | CY3: phases_La2O3 | CZ3: oxide_phase_La2O3 | DA3: GM_CeO2 | DB3: GM_system_CeO2 | DC3: G_metal_CeO2 | DD3: dG_CeO2_per_O2 | DE3: phases_CeO2 | DF3: oxide_phase_CeO2
A4: 500 | B4: 226.85 | C4: -73444.479 | D4: -73389.029 | E4: -18012.016 | F4: -264411.73 | G4: CUPRITE#1;FCC_A1#1 | H4: CUPRITE#1 | I4: -89642.551 | J4: -89642.551 | K4: -18012.016 | L4: -218339.1 | M4: CUO#1 | N4: CUO#1 | O4: -341247.42 | P4: -341247.42 | Q4: -15643.623 | R4: -1012426.2 | S4: CORUNDUM#1;FCC_A1#1 | T4: CORUNDUM#1 | U4: -308692.03 | V4: -308692.03 | W4: -17846.112 | X4: -1094868.8 | Y4: HALITE#1 | Z4: HALITE#1 | AA4: -311415.68 | AB4: -311156.37 | AC4: -10664.618 | AD4: -819375.35 | AE4: GAS#1;QUARTZ#1 | AF4: QUARTZ#1 | AG4: -323627.46 | AH4: -323355.94 | AI4: -16901.095 | AJ4: -849774.21 | AK4: GAS#1;RUTILE#1 | AL4: RUTILE#1 | AM4: -151649.53 | AN4: -151649.53 | AO4: -15154.713 | AP4: -472081.61 | AQ4: BCC_A2#1;SPINEL#1 | AR4: NOT_FOUND | AS4: -328264.22 | AT4: -328264.22 | AU4: -22354.311 | AV4: -1164141.2 | AW4: HALITE#1 | AX4: HALITE#1 | AY4: -376299.97 | AZ4: -375975.77 | BA4: -21167.402 | BB4: -1003525.4 | BC4: GAS#1;ZRO2_MONO#1 | BD4: ZRO2_MONO#1 | BE4: -235244.09 | BF4: -235244.09 | BG4: -13193.085 | BH4: -662349.11 | BI4: CORUNDUM#1 | BJ4: CORUNDUM#1 | BK4: -209433.61 | BL4: -209433.61 | BM4: -17713.156 | BN4: -698101.06 | BO4: CBCC_A12#1;HALITE#1 | BP4: HALITE#1 | BQ4: -130720.41 | BR4: -130720.41 | BS4: -16450.818 | BT4: -385772.95 | BU4: HALITE#1 | BV4: HALITE#1 | BW4: -133470.04 | BX4: -133470.04 | BY4: -16529.301 | BZ4: -396614.49 | CA4: HALITE#1;HCP_A3#1 | CB4: HALITE#1 | CF4: -127614.51 | CH4: SSUB3 | CM4: Error: Thermo-Calc calculation error: se.thermocalc.core.CalculationEngineException: ERROR IN QTHISS : TOO MANY ITERATIONS | CO4: -232013.43 | CP4: -232013.43 | CQ4: -16917.985 | CR4: -531896.16 | CS4: V2O5#1 | CT4: V2O5#1 | CU4: -372348.45 | CV4: -372348.45 | CW4: -30055.178 | CX4: -1096880.9 | CY4: M2O3A#1 | CZ4: NOT_FOUND | DD4: -1125260.7 | DF4: SSUB3
A5: 550 | B5: 276.85 | C5: -75626.29 | D5: -75571.035 | E5: -20387.806 | F5: -256894.64 | G5: CUPRITE#1;FCC_A1#1 | H5: CUPRITE#1 | I5: -91377.315 | J5: -91377.315 | K5: -20387.806 | L5: -209421.77 | M5: CUO#1 | N5: CUO#1 | O5: -342293.35 | P5: -342293.35 | Q5: -17787.565 | R5: -1001949.2 | S5: CORUNDUM#1;FCC_A1#1 | T5: CORUNDUM#1 | U5: -309964.34 | V5: -309964.34 | W5: -20217.612 | X5: -1084110.3 | Y5: HALITE#1 | Z5: HALITE#1 | AA5: -312606.92 | AB5: -312351.97 | AC5: -12227.27 | AD5: -810281.63 | AE5: GAS#1;QUARTZ#1 | AF5: QUARTZ#1 | AG5: -325057.24 | AH5: -324789.84 | AI5: -19193.487 | AJ5: -840666.35 | AK5: GAS#1;RUTILE#1 | AL5: RUTILE#1 | AM5: -153434.74 | AN5: -153434.74 | AO5: -17286.519 | AP5: -463854.03 | AQ5: BCC_A2#1;SPINEL#1 | AR5: NOT_FOUND | AS5: -329874.46 | AT5: -329874.46 | AU5: -25197.426 | AV5: -1153791.1 | AW5: HALITE#1 | AX5: HALITE#1 | AY5: -377725.01 | AZ5: -377404.94 | BA5: -23895.673 | BB5: -993967.48 | BC5: GAS#1;ZRO2_MONO#1 | BD5: ZRO2_MONO#1 | BE5: -236695.35 | BF5: -236695.35 | BG5: -15077.586 | BH5: -653569.17 | BI5: CORUNDUM#1 | BJ5: CORUNDUM#1 | BK5: -211574.22 | BL5: -211574.22 | BM5: -20127.467 | BN5: -690730.07 | BO5: CBCC_A12#1;HALITE#1 | BP5: HALITE#1 | BQ5: -132399.19 | BR5: -132399.19 | BS5: -18734.614 | BT5: -376815.66 | BU5: HALITE#1 | BV5: HALITE#1 | BW5: -135554.63 | BX5: -135554.63 | BY5: -18788.803 | BZ5: -389329.04 | CA5: HALITE#1;HCP_A3#1 | CB5: HALITE#1 | CF5: -129999.32 | CH5: SSUB3 | CM5: Error: Thermo-Calc calculation error: se.thermocalc.core.CalculationEngineException: ERROR IN QTHISS : TOO MANY ITERATIONS | CO5: -233523.6 | CP5: -233523.6 | CQ5: -19185.692 | CR5: -523205.64 | CS5: V2O5#1;V3O7#1 | CT5: V2O5#1 | CU5: -374280.07 | CV5: -374280.07 | CW5: -33674.505 | CX5: -1087389 | CY5: M2O3A#1 | CZ5: NOT_FOUND | DD5: -1130278.5 | DF5: SSUB3
A6: 600 | B6: 326.85 | C6: -77918.124 | D6: -77863.073 | E6: -22883.974 | F6: -249412.37 | G6: CUPRITE#1;FCC_A1#1 | H6: CUPRITE#1 | I6: -93226.43 | J6: -93226.43 | K6: -22883.974 | L6: -200577.3 | M6: CUO#1;CUPRITE#1 | N6: CUO#1 | O6: -343439.04 | P6: -343439.04 | Q6: -20056.834 | R6: -991493.89 | S6: CORUNDUM#1;FCC_A1#1 | T6: CORUNDUM#1 | U6: -311342.51 | V6: -311342.51 | W6: -22714.972 | X6: -1073379.6 | Y6: HALITE#1 | Z6: HALITE#1 | AA6: -313893.47 | AB6: -313642.86 | AC6: -13898.083 | AD6: -801221.86 | AE6: GAS#1;QUARTZ#1 | AF6: QUARTZ#1 | AG6: -326591.83 | AH6: -326328.44 | AI6: -21615.892 | AJ6: -831599.12 | AK6: GAS#1;RUTILE#1 | AL6: RUTILE#1 | AM6: -155350.44 | AN6: -155350.44 | AO6: -19557.489 | AP6: -455726.3 | AQ6: BCC_A2#1;SPINEL#1 | AR6: NOT_FOUND | AS6: -331598.69 | AT6: -331598.69 | AU6: -28174.365 | AV6: -1143485.5 | AW6: HALITE#1 | AX6: HALITE#1 | AY6: -379254.7 | AZ6: -378938.72 | BA6: -26754.746 | BB6: -984448.87 | BC6: GAS#1;ZRO2_MONO#1 | BD6: ZRO2_MONO#1 | BE6: -238255.14 | BF6: -238255.14 | BG6: -17083.087 | BH6: -644845.86 | BI6: CORUNDUM#1 | BJ6: CORUNDUM#1 | BK6: -213827.82 | BL6: -213827.82 | BM6: -22683.17 | BN6: -683384.45 | BO6: CBCC_A12#1;HALITE#1 | BP6: HALITE#1 | BQ6: -134207.65 | BR6: -134207.65 | BS6: -21169.097 | BT6: -367931.93 | BU6: HALITE#1 | BV6: HALITE#1 | BW6: -137758.18 | BX6: -137758.18 | BY6: -21179.155 | BZ6: -382113.93 | CA6: HALITE#1;HCP_A3#1 | CB6: HALITE#1 | CF6: -132502.22 | CH6: SSUB3 | CI6: -262962.27 | CJ6: -262962.27 | CK6: -5351.862 | CL6: -742844.61 | CM6: B2O3#1;BETA_RHOMBO_B#1 | CN6: B2O3#1 | CO6: -235135 | CP6: -235135 | CQ6: -21575.627 | CR6: -514557.02 | CS6: V2O5#1 | CT6: V2O5#1 | CU6: -376323.82 | CV6: -376323.82 | CW6: -37452.309 | CX6: -1077915.8 | CY6: M2O3A#1 | CZ6: NOT_FOUND | DD6: -1135625 | DF6: SSUB3
A7: 650 | B7: 376.85 | C7: -80312.452 | D7: -80257.615 | E7: -25491.622 | F7: -241965.31 | G7: CUPRITE#1;FCC_A1#1 | H7: CUPRITE#1 | I7: -95181.94 | J7: -95181.94 | K7: -25491.622 | L7: -191801.6 | M7: CUO#1;CUPRITE#1 | N7: CUO#1 | O7: -344678.58 | P7: -344678.58 | Q7: -22443.344 | R7: -981061.23 | S7: CORUNDUM#1;FCC_A1#1 | T7: CORUNDUM#1 | U7: -312819.31 | V7: -312819.31 | W7: -25329.833 | X7: -1062674.7 | Y7: HALITE#1 | Z7: HALITE#1 | AA7: -315269.72 | AB7: -315023.42 | AC7: -15669.616 | AD7: -792196.63 | AE7: GAS#1;QUARTZ#1 | AF7: QUARTZ#1 | AG7: -328224.19 | AH7: -327964.94 | AI7: -24159.617 | AJ7: -822570.03 | AK7: GAS#1;RUTILE#1 | AL7: RUTILE#1 | AM7: -157391.4 | AN7: -157391.4 | AO7: -21961.62 | AP7: -447699.44 | AQ7: BCC_A2#1;SPINEL#1 | AR7: NOT_FOUND | AS7: -333428.66 | AT7: -333428.66 | AU7: -31277.988 | AV7: -1133215.8 | AW7: HALITE#1 | AX7: HALITE#1 | AY7: -380881.82 | AZ7: -380569.91 | BA7: -29735.679 | BB7: -974966.87 | BC7: GAS#1;ZRO2_MONO#1 | BD7: ZRO2_MONO#1 | BE7: -239915.56 | BF7: -239915.56 | BG7: -19201.427 | BH7: -636173.7 | BI7: CORUNDUM#1 | BJ7: CORUNDUM#1 | BK7: -216186.24 | BL7: -216186.24 | BM7: -25371.836 | BN7: -676058.38 | BO7: CBCC_A12#1;HALITE#1 | BP7: HALITE#1 | BQ7: -136130.72 | BR7: -136130.72 | BS7: -23753.604 | BT7: -359072.76 | BU7: FCC_A1#1;HALITE#1 | BV7: HALITE#1 | BW7: -140072.08 | BX7: -140072.08 | BY7: -23692.248 | BZ7: -374960.89 | CA7: HALITE#1;HCP_A3#1 | CB7: HALITE#1 | CF7: -135117.11 | CH7: SSUB3 | CM7: Error: Thermo-Calc calculation error: se.thermocalc.core.CalculationEngineException: ERROR IN QTHISS : TOO MANY ITERATIONS | CO7: -236840.93 | CP7: -236840.93 | CQ7: -24079.007 | CR7: -505948.47 | CS7: V2O5#1;V3O7#1 | CT7: V2O5#1 | CU7: -378471.57 | CV7: -378471.57 | CW7: -41346.017 | CX7: -1068500.9 | CY7: GAS#1;M2O3A#1 | CZ7: NOT_FOUND | DD7: -1141277.3 | DF7: SSUB3
A8: 700 | B8: 426.85 | C8: -82802.797 | D8: -82748.181 | E8: -28203.163 | F8: -234553.45 | G8: CUPRITE#1;FCC_A1#1 | H8: CUPRITE#1 | I8: -97236.935 | J8: -97236.935 | K8: -28203.163 | L8: -183090.73 | M8: CUO#1;CUPRITE#1 | N8: CUO#1 | O8: -346006.55 | P8: -346006.55 | Q8: -24940.287 | R8: -970650.78 | S8: CORUNDUM#1;FCC_A1#1 | T8: CORUNDUM#1 | U8: -314388.37 | V8: -314388.37 | W8: -28055.214 | X8: -1051992.4 | Y8: HALITE#1 | Z8: HALITE#1 | AA8: -316730.71 | AB8: -316488.7 | AC8: -17535.413 | AD8: -783206.03 | AE8: GAS#1;QUARTZ#1 | AF8: QUARTZ#1 | AG8: -329948.06 | AH8: -329692.84 | AI8: -26817.229 | AJ8: -813576.27 | AK8: GAS#1;RUTILE#1 | AL8: RUTILE#1 | AM8: -159553.78 | AN8: -159553.78 | AO8: -24494.405 | AP8: -439775.63 | AQ8: BCC_A2#1;SPINEL#1 | AR8: NOT_FOUND | AS8: -335357.22 | AT8: -335357.22 | AU8: -34502.384 | AV8: -1122973.4 | AW8: HALITE#1 | AX8: HALITE#1 | AY8: -382600.09 | AZ8: -382292.22 | BA8: -32830.878 | BB8: -965518.71 | BC8: GAS#1;ZRO2_MONO#1 | BD8: ZRO2_MONO#1 | BE8: -241669.74 | BF8: -241669.74 | BG8: -21425.75 | BH8: -627547.45 | BI8: CORUNDUM#1 | BJ8: CORUNDUM#1 | BK8: -218642.5 | BL8: -218642.5 | BM8: -28186.268 | BN8: -668746.79 | BO8: CBCC_A12#1;HALITE#1 | BP8: HALITE#1 | BQ8: -138159.14 | BR8: -138159.14 | BS8: -26466.209 | BT8: -350253.47 | BU8: FCC_A1#1;HALITE#1 | BV8: HALITE#1 | BW8: -142489.02 | BX8: -142489.02 | BY8: -26324.525 | BZ8: -367856.37 | CA8: FCC_A1#1;HALITE#1 | CB8: HALITE#1 | CF8: -137846.18 | CH8: SSUB3 | CM8: Error: Thermo-Calc calculation error: se.thermocalc.core.CalculationEngineException: ERROR IN QTHISS : TOO MANY ITERATIONS | CO8: -238635.7 | CP8: -238635.7 | CQ8: -26688.329 | CR8: -497378.61 | CS8: V2O5#1 | CT8: V2O5#1 | CU8: -380716.33 | CV8: -380716.33 | CW8: -45348.971 | CX8: -1059138.5 | CY8: M2O3A#1 | CZ8: NOT_FOUND | DD8: -1147215.1 | DF8: SSUB3
A9: 750 | B9: 476.85 | C9: -85383.53 | D9: -85329.142 | E9: -31012.049 | F9: -227176.66 | G9: CUPRITE#1;FCC_A1#1 | H9: CUPRITE#1 | I9: -99385.375 | J9: -99385.375 | K9: -31012.049 | L9: -174441.08 | M9: CUO#1 | N9: CUO#1 | O9: -347418.06 | P9: -347418.06 | Q9: -27541.91 | R9: -960261.32 | S9: CORUNDUM#1;FCC_A1#1 | T9: CORUNDUM#1 | U9: -316044.09 | V9: -316044.09 | W9: -30885.237 | X9: -1041329.6 | Y9: HALITE#1 | Z9: HALITE#1 | AA9: -318272.88 | AB9: -318035.15 | AC9: -19489.833 | AD9: -774252.48 | AE9: GAS#1;QUARTZ#1 | AF9: QUARTZ#1 | AG9: -331757.86 | AH9: -331506.64 | AI9: -29582.304 | AJ9: -804614.94 | AK9: GAS#1;RUTILE#1 | AL9: RUTILE#1 | AM9: -161835.22 | AN9: -161835.22 | AO9: -27152.639 | AP9: -431959.27 | AQ9: BCC_A2#1;SPINEL#1 | AR9: NOT_FOUND | AS9: -337378.09 | AT9: -337378.09 | AU9: -37885.73 | AV9: -1112664.6 | AW9: HALITE#1 | AX9: HALITE#1 | AY9: -384403.96 | AZ9: -384100.09 | BA9: -36033.815 | BB9: -956101.74 | BC9: GAS#1;ZRO2_MONO#1 | BD9: ZRO2_MONO#1 | BE9: -243511.67 | BF9: -243511.67 | BG9: -23750.259 | BH9: -618962.23 | BI9: CORUNDUM#1 | BJ9: CORUNDUM#1 | BK9: -221190.53 | BL9: -221190.53 | BM9: -31120.262 | BN9: -661445.27 | BO9: CBCC_A12#1;HALITE#1 | BP9: HALITE#1 | BQ9: -140285.57 | BR9: -140285.57 | BS9: -29289.648 | BT9: -341486.67 | BU9: FCC_A1#1;HALITE#1 | BV9: HALITE#1 | BW9: -145002.75 | BX9: -145002.75 | BY9: -29094.988 | BZ9: -360744.71 | CA9: FCC_A1#1;HALITE#1 | CB9: HALITE#1 | CF9: -140671.15 | CH9: SSUB3 | CI9: -266817.85 | CJ9: -266817.85 | CK9: -8323.3279 | CL9: -717218.72 | CM9: IONIC_LIQ#1 | CN9: NOT_FOUND | CO9: -240514.53 | CP9: -240514.53 | CQ9: -29397.107 | CR9: -488846.66 | CS9: V2O5#1 | CT9: V2O5#1 | CU9: -383052.06 | CV9: -383052.06 | CW9: -49455.563 | CX9: -1049823.1 | CY9: M2O3A#1 | CZ9: NOT_FOUND | DD9: -1153421 | DF9: SSUB3
A10: 800 | B10: 526.85 | C10: -88049.722 | D10: -87995.569 | E10: -33912.573 | F10: -219834.74 | G10: CUPRITE#1;FCC_A1#1 | H10: CUPRITE#1 | I10: -101621.95 | J10: -101621.95 | K10: -33912.573 | L10: -165849.34 | M10: CUO#1;CUPRITE#1 | N10: CUO#1 | O10: -348908.68 | P10: -348908.68 | Q10: -30243.549 | R10: -949890.9 | S10: CORUNDUM#1;FCC_A1#1 | T10: CORUNDUM#1 | U10: -317781.49 | V10: -317781.49 | W10: -33814.914 | X10: -1030682.8 | Y10: HALITE#1 | Z10: HALITE#1 | AA10: -319894.45 | AB10: -319660.96 | AC10: -21527.916 | AD10: -765342.12 | AE10: GAS#1;QUARTZ#1 | AF10: QUARTZ#1 | AG10: -333648.59 | AH10: -333401.35 | AI10: -32449.237 | AJ10: -795683.24 | AK10: GAS#1;RUTILE#1 | AL10: RUTILE#1 | AM10: -164235.13 | AN10: -164235.13 | AO10: -29934.315 | AP10: -424258.6 | AQ10: BCC_A2#1;SPINEL#1 | AR10: NOT_FOUND | AS10: -339485.7 | AT10: -339485.7 | AU10: -41398.183 | AV10: -1102333.1 | AW10: HALITE#1 | AX10: HALITE#1 | AY10: -386288.54 | AZ10: -385988.66 | BA10: -39338.82 | BB10: -946713.5 | BC10: GAS#1;ZRO2_MONO#1 | BD10: ZRO2_MONO#1 | BE10: -245436.05 | BF10: -245436.05 | BG10: -26170.02 | BH10: -610413.51 | BI10: CORUNDUM#1 | BJ10: CORUNDUM#1 | BK10: -223825.03 | BL10: -223825.03 | BM10: -34168.409 | BN10: -654150.01 | BO10: CBCC_A12#1;HALITE#1 | BP10: HALITE#1 | BQ10: -142503.86 | BR10: -142503.86 | BS10: -32215.643 | BT10: -332770.85 | BU10: FCC_A1#1;HALITE#1 | BV10: HALITE#1 | BW10: -147607.81 | BX10: -147607.8 | BY10: -31971.301 | BZ10: -353675.32 | CA10: FCC_A1#1;HALITE#1 | CB10: HALITE#1 | CF10: -143586.87 | CH10: SSUB3 | CM10: Error: Thermo-Calc calculation error: se.thermocalc.core.CalculationEngineException: ERROR IN QTHISS : TOO MANY ITERATIONS | CO10: -242473.37 | CP10: -242473.37 | CQ10: -32199.681 | CR10: -480352.39 | CS10: V2O5#1 | CT10: V2O5#1 | CU10: -385473.45 | CV10: -385473.45 | CW10: -53660.986 | CX10: -1040550.2 | CY10: M2O3A#1 | CZ10: NOT_FOUND | DD10: -1159879.6 | DF10: SSUB3
A11: 850 | B11: 576.85 | C11: -90797.025 | D11: -90743.112 | E11: -36899.716 | F11: -212527.52 | G11: CUPRITE#1;FCC_A1#1 | H11: CUPRITE#1 | I11: -103941.94 | J11: -103941.94 | K11: -36899.716 | L11: -157312.57 | M11: CUO#1;CUPRITE#1 | N11: CUO#1 | O11: -350474.41 | P11: -350474.41 | Q11: -33041.63 | R11: -939536.76 | S11: CORUNDUM#1;FCC_A1#1 | T11: CORUNDUM#1 | U11: -319596.14 | V11: -319596.14 | W11: -36839.99 | X11: -1020048.8 | Y11: HALITE#1 | Z11: HALITE#1 | AA11: -321596.13 | AB11: -321366.86 | AC11: -23645.27 | AD11: -756487.34 | AE11: GAS#1;QUARTZ#1 | AF11: QUARTZ#1 | AG11: -335615.78 | AH11: -335372.5 | AI11: -35413.09 | AJ11: -786778.5 | AK11: GAS#1;RUTILE#1 | AL11: RUTILE#1 | AM11: -170489.53 | AN11: -166862.3 | AO11: -32838.631 | AP11: -431625.08 | AQ11: BCC_A2#1;HALITE#1 | AR11: HALITE#1 | AS11: -341675.16 | AT11: -341675.16 | AU11: -45016.344 | AV11: -1092012.2 | AW11: HALITE#1 | AX11: HALITE#1 | AY11: -388249.48 | AZ11: -387953.56 | BA11: -42740.921 | BB11: -937351.75 | BC11: GAS#1;ZRO2_MONO#1 | BD11: ZRO2_MONO#1 | BE11: -247438.19 | BF11: -247438.19 | BG11: -28680.813 | BH11: -601897.11 | BI11: CORUNDUM#1 | BJ11: CORUNDUM#1 | BK11: -226541.35 | BL11: -226541.34 | BM11: -37325.959 | BN11: -646857.71 | BO11: CBCC_A12#1;HALITE#1 | BP11: HALITE#1 | BQ11: -144808.69 | BR11: -144808.69 | BS11: -35237.984 | BT11: -324103.01 | BU11: FCC_A1#1;HALITE#1 | BV11: HALITE#1 | BW11: -150299.4 | BX11: -150299.38 | BY11: -34949.563 | BZ11: -346642.7 | CA11: FCC_A1#1;HALITE#1 | CB11: HALITE#1 | CF11: -146588.79 | CH11: SSUB3 | CM11: Error: Thermo-Calc calculation error: se.thermocalc.core.CalculationEngineException: ERROR IN QTHISS : TOO MANY ITERATIONS | CO11: -244508.83 | CP11: -244508.83 | CQ11: -35091.1 | CR11: -471896.07 | CS11: V2O5#1 | CT11: V2O5#1 | CU11: -387975.84 | CV11: -387975.84 | CW11: -57961.087 | CX11: -1031315.6 | CY11: M2O3A#1 | CZ11: NOT_FOUND | DD11: -1166577.3 | DF11: SSUB3
