Workbook

Sheet Formation Energies
A1: T (K) | B1: CeO2 | C1: CaO | D1: La2O3 | E1: MgO | F1: ZrO2 | G1: Al2O3 | H1: TiO2 | I1: SiO2 | J1: MnO | K1: Cr2O3 | L1: V2O5 | M1: FeO | N1: CoO | O1: NiO | P1: PbO | Q1: Cu2O | R1: CuO | S1: B2O3
A2: 500 | B2: -1125.2607 | C2: -1164.1412 | D2: -1096.8809 | E2: -1094.8688 | F2: -1003.5254 | G2: -1012.4262 | H2: -849.77421 | I2: -819.37535 | J2: -698.10106 | K2: -662.34911 | L2: -531.89616 | M2: -472.08161 | N2: -396.61449 | O2: -385.77295 | P2: -127.61451 | Q2: -264.41173 | R2: -218.3391
A3: 550 | B3: -1130.2785 | C3: -1153.7911 | D3: -1087.389 | E3: -1084.1103 | F3: -993.96748 | G3: -1001.9492 | H3: -840.66635 | I3: -810.28163 | J3: -690.73007 | K3: -653.56917 | L3: -523.20564 | M3: -463.85403 | N3: -389.32904 | O3: -376.81566 | P3: -129.99932 | Q3: -256.89464 | R3: -209.42177
A4: 600 | B4: -1135.625 | C4: -1143.4855 | D4: -1077.9158 | E4: -1073.3796 | F4: -984.44887 | G4: -991.49389 | H4: -831.59912 | I4: -801.22186 | J4: -683.38445 | K4: -644.84586 | L4: -514.55702 | M4: -455.7263 | N4: -382.11393 | O4: -367.93193 | P4: -132.50222 | Q4: -249.41237 | R4: -200.5773 | S4: -742.84461
A5: 650 | B5: -1141.2773 | C5: -1133.2158 | D5: -1068.5009 | E5: -1062.6747 | F5: -974.96687 | G5: -981.06123 | H5: -822.57003 | I5: -792.19663 | J5: -676.05838 | K5: -636.1737 | L5: -505.94847 | M5: -447.69944 | N5: -374.96089 | O5: -359.07276 | P5: -135.11711 | Q5: -241.96531 | R5: -191.8016
A6: 700 | B6: -1147.2151 | C6: -1122.9734 | D6: -1059.1385 | E6: -1051.9924 | F6: -965.51871 | G6: -970.65078 | H6: -813.57627 | I6: -783.20603 | J6: -668.74679 | K6: -627.54745 | L6: -497.37861 | M6: -439.77563 | N6: -367.85637 | O6: -350.25347 | P6: -137.84618 | Q6: -234.55345 | R6: -183.09073
A7: 750 | B7: -1153.421 | C7: -1112.6646 | D7: -1049.8231 | E7: -1041.3296 | F7: -956.10174 | G7: -960.26132 | H7: -804.61494 | I7: -774.25248 | J7: -661.44527 | K7: -618.96223 | L7: -488.84666 | M7: -431.95927 | N7: -360.74471 | O7: -341.48667 | P7: -140.67115 | Q7: -227.17666 | R7: -174.44108 | S7: -717.21872
A8: 800 | B8: -1159.8796 | C8: -1102.3331 | D8: -1040.5502 | E8: -1030.6828 | F8: -946.7135 | G8: -949.8909 | H8: -795.68324 | I8: -765.34212 | J8: -654.15001 | K8: -610.41351 | L8: -480.35239 | M8: -424.2586 | N8: -353.67532 | O8: -332.77085 | P8: -143.58687 | Q8: -219.83474 | R8: -165.84934
A9: 850 | B9: -1166.5773 | C9: -1092.0122 | D9: -1031.3156 | E9: -1020.0488 | F9: -937.35175 | G9: -939.53676 | H9: -786.7785 | I9: -756.48734 | J9: -646.85771 | K9: -601.89711 | L9: -471.89607 | M9: -431.62508 | N9: -346.6427 | O9: -324.10301 | P9: -146.58879 | Q9: -212.52752 | R9: -157.31257
A10: 900 | B10: -1173.5018 | C10: -1081.6933 | D10: -1022.1155 | E10: -1009.4242 | F10: -928.01447 | G10: -929.19559 | H10: -777.89823 | I10: -747.69801 | J10: -639.56547 | K10: -593.40918 | L10: -463.47832 | M10: -424.64468 | N10: -339.64148 | O10: -315.4797 | P10: -149.67287 | Q10: -205.25488 | R10: -148.82813
A11: 950 | B11: -1180.6425 | C11: -1071.369 | D11: -1012.9467 | E11: -998.3084 | F11: -918.69983 | G11: -918.6134 | H11: -769.04011 | I11: -738.93017 | J11: -632.27078 | K11: -584.94617 | L11: -455.10016 | M11: -417.86599 | N11: -332.66648 | O11: -306.89735 | P11: -152.83553 | Q11: -198.01671 | R11: -140.39367
A12: 1000 | B12: -1187.9894 | C12: -1061.0322 | D12: -1003.8062 | E12: -986.76559 | F12: -909.4062 | G12: -907.53028 | H12: -760.20192 | I12: -730.18265 | J12: -624.88011 | K12: -576.50625 | L12: -448.03163 | M12: -411.1916 | N12: -325.71261 | O12: -298.35386 | P12: -156.07356 | Q12: -190.81297 | R12: -132.00708
A13: 1050 | B13: -1195.5337 | C13: -1050.6765 | D13: -994.69133 | E13: -975.2182 | F13: -900.13212 | G13: -896.46212 | H13: -751.38159 | I13: -721.45448 | J13: -617.35153 | K13: -568.08357 | L13: -441.10698 | M13: -404.558 | N13: -318.77475 | O13: -289.84296 | P13: -159.38404 | Q13: -183.64367 | R13: -123.66649
A14: 1100 | B14: -1203.2674 | C14: -1040.2961 | D14: -985.59963 | E14: -963.66732 | F14: -890.87624 | G14: -885.40917 | H14: -742.57721 | I14: -712.74485 | J14: -609.82306 | K14: -559.67666 | L14: -434.23744 | M14: -397.93993 | N14: -311.8477 | O14: -281.36285 | P14: -162.76434 | Q14: -176.5088 | R14: -115.3702
A15: 1150 | B15: -1211.1831 | C15: -1029.3498 | D15: -976.47579 | E15: -952.11396 | F15: -881.59901 | G15: -874.37159 | H15: -733.787 | I15: -704.06662 | J15: -602.2935 | K15: -551.28283 | L15: -427.42604 | M15: -391.34079 | N15: -304.92601 | O15: -272.91096 | P15: -166.21208 | Q15: -169.40836 | R15: -107.11665
A16: 1200 | B16: -1219.2741 | C16: -1018.1853 | D16: -967.17995 | E16: -940.559 | F16: -872.20568 | G16: -863.34952 | H16: -724.85224 | I16: -695.48865 | J16: -594.76183 | K16: -542.89956 | L16: -420.67725 | M16: -384.74477 | N16: -298.00387 | O16: -264.48496 | P16: -170.14241 | Q16: -162.3423 | R16: -98.904408
A17: 1250 | B17: -1227.5343 | C17: -1007.0262 | D17: -957.60498 | E17: -929.00324 | F17: -862.84096 | G17: -852.34303 | H17: -715.92039 | I17: -686.9256 | J17: -587.22717 | K17: -534.5244 | L17: -413.99689 | M17: -378.1411 | N17: -291.07487 | O17: -256.08285 | P17: -174.28097 | Q17: -155.31051 | R17: -90.732113
A18: 1300 | B18: -1235.9578 | C18: -995.87269 | D18: -948.05194 | E18: -917.44741 | F18: -853.50376 | G18: -841.35215 | H18: -707.00914 | I18: -678.37644 | J18: -579.68876 | K18: -526.15503 | L18: -407.39177 | M18: -371.57165 | N18: -284.13171 | O18: -247.70296 | P18: -178.48455 | Q18: -148.31318 | R18: -82.59867
A19: 1350 | B19: -1244.5395 | C19: -984.72479 | D19: -938.52095 | E19: -905.89216 | F19: -844.19307 | G19: -830.37689 | H19: -698.11712 | I19: -669.84029 | J19: -572.14593 | K19: -517.78917 | L19: -400.86941 | M19: -365.035 | N19: -277.16578 | O19: -239.34392 | P19: -182.75065 | Q19: -141.35124 | R19: -74.503437
... A24: 1600 | B24: -1289.6596 | C24: -929.07376 | D24: -891.20029 | E24: -810.83951 | F24: -798.93589 | G24: -775.73345 | H24: -653.90241 | I24: -627.33474 | J24: -531.59558 | K24: -475.93722 | L24: -369.74926 | M24: -332.80462 | N24: -242.22023 | O24: -197.8329 | P24: -204.94323 | Q24: -105.85504 | R24: -57.547943
A25: 1650 | B25: -1299.098 | C25: -917.96174 | D25: -881.8035 | E25: -790.64627 | F25: -789.96461 | G25: -764.85066 | H25: -645.10118 | I25: -618.86663 | J25: -522.81336 | K25: -467.54804 | L25: -363.86003 | M25: -314.09725 | N25: -235.28968 | O25: -189.58549 | P25: -209.54101 | Q25: -101.29901 | R25: -54.763087 | S25: -589.11539
A26: 1700 | B26: -1308.6664 | C26: -906.85587 | D26: -872.4292 | E26: -770.49768 | F26: -781.01348 | G26: -753.98284 | H26: -636.3119 | I26: -610.02241 | J26: -514.01258 | K26: -459.14806 | L26: -358.08751 | M26: -309.77515 | N26: -228.3873 | O26: -181.35681 | P26: -214.18804 | Q26: -96.714843 | R26: -51.989006 | S26: -582.25336
A27: 1750 | B27: -1318.3616 | C27: -895.75613 | D27: -863.07737 | E27: -750.39282 | F27: -772.08162 | G27: -743.12974 | H27: -627.53401 | I27: -600.09213 | J27: -505.19516 | K27: -450.73531 | L27: -352.43054 | M27: -305.49798 | N27: -221.51494 | O27: -172.70208 | P27: -218.88288 | Q27: -92.104228 | R27: -49.227068
A28: 1800 | B28: -1328.1808 | C28: -878.77799 | D28: -853.74793 | E28: -730.33088 | F28: -763.16813 | G28: -732.29108 | H28: -618.76705 | I28: -590.18934 | J28: -496.36288 | K28: -442.30782 | L28: -346.88653 | M28: -301.27684 | N28: -214.08761 | O28: -163.49179 | P28: -223.62415 | Q28: -87.468853 | R28: -46.478698 | S28: -568.57302
A29: 1850 | B29: -1338.1212 | C29: -859.33993 | D29: -844.44074 | E29: -710.31104 | F29: -754.27211 | G29: -721.46652 | H29: -610.01068 | I29: -580.29969 | J29: -487.5174 | K29: -433.86359 | L29: -341.45352 | M29: -296.51666 | N29: -206.36391 | O29: -154.29355 | P29: -228.41056 | Q29: -82.810412 | R29: -43.745446
A30: 1900 | B30: -1348.1801 | C30: -839.94582 | D30: -835.15562 | E30: -690.3325 | F30: -745.39257 | G30: -710.65567 | H30: -601.2647 | I30: -570.42286 | J30: -478.66026 | K30: -425.40062 | L30: -336.13407 | M30: -291.63279 | N30: -198.67425 | O30: -145.11038 | P30: -233.2409 | Q30: -78.130609 | R30: -41.02911 | S30: -554.94383
A31: 1950 | B31: -1358.3552 | C31: -820.59439 | D31: -825.8923 | E31: -670.39441 | F31: -736.5285 | G31: -699.85808 | H31: -592.46414 | I31: -560.55846 | J31: -469.79284 | K31: -416.91683 | L31: -330.92491 | M31: -286.78147 | N31: -191.02079 | O31: -135.94552 | P31: -238.114 | Q31: -73.431165 | R31: -38.331907 | S31: -548.14577
A32: 2000 | B32: -1368.644 | C32: -801.28432 | D32: -816.6504 | E32: -650.49588 | F32: -727.67878 | G32: -689.0732 | H32: -583.36712 | I32: -550.31391 | J32: -460.91633 | K32: -408.41008 | L32: -325.82145 | M32: -281.96124 | N32: -183.40566 | O32: -126.80326 | P32: -245.43637 | Q32: -68.713833 | R32: -35.656737

Sheet Reaction dG (Arithmetic)
A1: ΔG_rxn at 727°C (1000 K)
A2: Oxide | B2: ΔGf(oxide) kJ | C2: ΔGf(Cu₂O) kJ | E2: ΔG_rxn kJ | F2: Verdict
A3: CeO2 | B3: ='Formation Energies'!B12 -> -1187.9894 | C3: ='Formation Energies'!Q12 -> -190.81297 | D3: = | E3: =C3-B3 -> 997.17641 | F3: =IF(ISBLANK(B3),"Pending",IF(E3>0,"CANNOT reduce","CAN reduce")) -> CANNOT reduce
A4: CaO | B4: ='Formation Energies'!C12 -> -1061.0322 | C4: ='Formation Energies'!Q12 -> -190.81297 | D4: = | E4: =C4-B4 -> 870.21922 | F4: =IF(ISBLANK(B4),"Pending",IF(E4>0,"CANNOT reduce","CAN reduce")) -> CANNOT reduce
A5: La2O3 | B5: ='Formation Energies'!D12 -> -1003.8062 | C5: ='Formation Energies'!Q12 -> -190.81297 | D5: = | E5: =C5-B5 -> 812.99324 | F5: =IF(ISBLANK(B5),"Pending",IF(E5>0,"CANNOT reduce","CAN reduce")) -> CANNOT reduce
A6: MgO | B6: ='Formation Energies'!E12 -> -986.76559 | C6: ='Formation Energies'!Q12 -> -190.81297 | D6: = | E6: =C6-B6 -> 795.95262 | F6: =IF(ISBLANK(B6),"Pending",IF(E6>0,"CANNOT reduce","CAN reduce")) -> CANNOT reduce
A7: ZrO2 | B7: ='Formation Energies'!F12 -> -909.4062 | C7: ='Formation Energies'!Q12 -> -190.81297 | D7: = | E7: =C7-B7 -> 718.59323 | F7: =IF(ISBLANK(B7),"Pending",IF(E7>0,"CANNOT reduce","CAN reduce")) -> CANNOT reduce
A8: Al2O3 | B8: ='Formation Energies'!G12 -> -907.53028 | C8: ='Formation Energies'!Q12 -> -190.81297 | D8: = | E8: =C8-B8 -> 716.71731 | F8: =IF(ISBLANK(B8),"Pending",IF(E8>0,"CANNOT reduce","CAN reduce")) -> CANNOT reduce
A9: TiO2 | B9: ='Formation Energies'!H12 -> -760.20192 | C9: ='Formation Energies'!Q12 -> -190.81297 | D9: = | E9: =C9-B9 -> 569.38895 | F9: =IF(ISBLANK(B9),"Pending",IF(E9>0,"CANNOT reduce","CAN reduce")) -> CANNOT reduce
A10: SiO2 | B10: ='Formation Energies'!I12 -> -730.18265 | C10: ='Formation Energies'!Q12 -> -190.81297 | D10: = | E10: =C10-B10 -> 539.36968 | F10: =IF(ISBLANK(B10),"Pending",IF(E10>0,"CANNOT reduce","CAN reduce")) -> CANNOT reduce
A11: MnO | B11: ='Formation Energies'!J12 -> -624.88011 | C11: ='Formation Energies'!Q12 -> -190.81297 | D11: = | E11: =C11-B11 -> 434.06714 | F11: =IF(ISBLANK(B11),"Pending",IF(E11>0,"CANNOT reduce","CAN reduce")) -> CANNOT reduce
A12: Cr2O3 | B12: ='Formation Energies'!K12 -> -576.50625 | C12: ='Formation Energies'!Q12 -> -190.81297 | D12: = | E12: =C12-B12 -> 385.69328 | F12: =IF(ISBLANK(B12),"Pending",IF(E12>0,"CANNOT reduce","CAN reduce")) -> CANNOT reduce
A13: V2O5 | B13: ='Formation Energies'!L12 -> -448.03163 | C13: ='Formation Energies'!Q12 -> -190.81297 | D13: = | E13: =C13-B13 -> 257.21866 | F13: =IF(ISBLANK(B13),"Pending",IF(E13>0,"CANNOT reduce","CAN reduce")) -> CANNOT reduce
A14: FeO | B14: ='Formation Energies'!M12 -> -411.1916 | C14: ='Formation Energies'!Q12 -> -190.81297 | D14: = | E14: =C14-B14 -> 220.37862 | F14: =IF(ISBLANK(B14),"Pending",IF(E14>0,"CANNOT reduce","CAN reduce")) -> CANNOT reduce
A15: CoO | B15: ='Formation Energies'!N12 -> -325.71261 | C15: ='Formation Energies'!Q12 -> -190.81297 | D15: = | E15: =C15-B15 -> 134.89964 | F15: =IF(ISBLANK(B15),"Pending",IF(E15>0,"CANNOT reduce","CAN reduce")) -> CANNOT reduce
A16: NiO | B16: ='Formation Energies'!O12 -> -298.35386 | C16: ='Formation Energies'!Q12 -> -190.81297 | D16: = | E16: =C16-B16 -> 107.54089 | F16: =IF(ISBLANK(B16),"Pending",IF(E16>0,"CANNOT reduce","CAN reduce")) -> CANNOT reduce
A17: PbO | B17: ='Formation Energies'!P12 -> -156.07356 | C17: ='Formation Energies'!Q12 -> -190.81297 | D17: = | E17: =C17-B17 -> -34.739417 | F17: =IF(ISBLANK(B17),"Pending",IF(E17>0,"CANNOT reduce","CAN reduce")) -> CAN reduce
A18: B2O3 | B18: ='Formation Energies'!S12 -> 0 | C18: ='Formation Energies'!Q12 -> -190.81297 | D18: = | E18: =C18-B18 -> -190.81297 | F18: =IF(ISBLANK(B18),"Pending",IF(E18>0,"CANNOT reduce","CAN reduce")) -> CAN reduce
A20: ΔG_rxn at 1227°C (1500 K)
A21: Oxide | B21: ΔGf(oxide) kJ | C21: ΔGf(Cu₂O) kJ | E21: ΔG_rxn kJ | F21: Verdict
A22: CeO2 | B22: ='Formation Energies'!B22 -> -1271.1859 | C22: ='Formation Energies'!Q22 -> -114.87584 | D22: = | E22: =C22-B22 -> 1156.3101 | F22: =IF(ISBLANK(B22),"Pending",IF(E22>0,"CANNOT reduce","CAN reduce")) -> CANNOT reduce
A23: CaO | B23: ='Formation Energies'!C22 -> -951.31616 | C23: ='Formation Energies'!Q22 -> -114.87584 | D23: = | E23: =C23-B23 -> 836.44032 | F23: =IF(ISBLANK(B23),"Pending",IF(E23>0,"CANNOT reduce","CAN reduce")) -> CANNOT reduce
A24: La2O3 | B24: ='Formation Energies'!D22 -> -910.06137 | C24: ='Formation Energies'!Q22 -> -114.87584 | D24: = | E24: =C24-B24 -> 795.18553 | F24: =IF(ISBLANK(B24),"Pending",IF(E24>0,"CANNOT reduce","CAN reduce")) -> CANNOT reduce
A25: MgO | B25: ='Formation Energies'!E22 -> -851.36385 | C25: ='Formation Energies'!Q22 -> -114.87584 | D25: = | E25: =C25-B25 -> 736.48802 | F25: =IF(ISBLANK(B25),"Pending",IF(E25>0,"CANNOT reduce","CAN reduce")) -> CANNOT reduce
A26: ZrO2 | B26: ='Formation Energies'!F22 -> -816.94236 | C26: ='Formation Energies'!Q22 -> -114.87584 | D26: = | E26: =C26-B26 -> 702.06652 | F26: =IF(ISBLANK(B26),"Pending",IF(E26>0,"CANNOT reduce","CAN reduce")) -> CANNOT reduce
A27: Al2O3 | B27: ='Formation Energies'!G22 -> -797.54455 | C27: ='Formation Energies'!Q22 -> -114.87584 | D27: = | E27: =C27-B27 -> 682.66871 | F27: =IF(ISBLANK(B27),"Pending",IF(E27>0,"CANNOT reduce","CAN reduce")) -> CANNOT reduce
A28: TiO2 | B28: ='Formation Energies'!H22 -> -671.54374 | C28: ='Formation Energies'!Q22 -> -114.87584 | D28: = | E28: =C28-B28 -> 556.66791 | F28: =IF(ISBLANK(B28),"Pending",IF(E28>0,"CANNOT reduce","CAN reduce")) -> CANNOT reduce
A29: SiO2 | B29: ='Formation Energies'!I22 -> -644.30349 | C29: ='Formation Energies'!Q22 -> -114.87584 | D29: = | E29: =C29-B29 -> 529.42765 | F29: =IF(ISBLANK(B29),"Pending",IF(E29>0,"CANNOT reduce","CAN reduce")) -> CANNOT reduce
A30: MnO | B30: ='Formation Energies'!J22 -> -548.77908 | C30: ='Formation Energies'!Q22 -> -114.87584 | D30: = | E30: =C30-B30 -> 433.90324 | F30: =IF(ISBLANK(B30),"Pending",IF(E30>0,"CANNOT reduce","CAN reduce")) -> CANNOT reduce
A31: Cr2O3 | B31: ='Formation Energies'!K22 -> -492.69091 | C31: ='Formation Energies'!Q22 -> -114.87584 | D31: = | E31: =C31-B31 -> 377.81507 | F31: =IF(ISBLANK(B31),"Pending",IF(E31>0,"CANNOT reduce","CAN reduce")) -> CANNOT reduce
A32: V2O5 | B32: ='Formation Energies'!L22 -> -381.8741 | C32: ='Formation Energies'!Q22 -> -114.87584 | D32: = | E32: =C32-B32 -> 266.99826 | F32: =IF(ISBLANK(B32),"Pending",IF(E32>0,"CANNOT reduce","CAN reduce")) -> CANNOT reduce
A33: FeO | B33: ='Formation Energies'!M22 -> -345.61006 | C33: ='Formation Energies'!Q22 -> -114.87584 | D33: = | E33: =C33-B33 -> 230.73422 | F33: =IF(ISBLANK(B33),"Pending",IF(E33>0,"CANNOT reduce","CAN reduce")) -> CANNOT reduce
A34: CoO | B34: ='Formation Energies'!N22 -> -256.15619 | C34: ='Formation Energies'!Q22 -> -114.87584 | D34: = | E34: =C34-B34 -> 141.28036 | F34: =IF(ISBLANK(B34),"Pending",IF(E34>0,"CANNOT reduce","CAN reduce")) -> CANNOT reduce
A35: NiO | B35: ='Formation Energies'!O22 -> -214.3824 | C35: ='Formation Energies'!Q22 -> -114.87584 | D35: = | E35: =C35-B35 -> 99.506563 | F35: =IF(ISBLANK(B35),"Pending",IF(E35>0,"CANNOT reduce","CAN reduce")) -> CANNOT reduce
A36: PbO | B36: ='Formation Energies'!P22 -> -195.90167 | C36: ='Formation Energies'!Q22 -> -114.87584 | D36: = | E36: =C36-B36 -> 81.025835 | F36: =IF(ISBLANK(B36),"Pending",IF(E36>0,"CANNOT reduce","CAN reduce")) -> CANNOT reduce
A37: B2O3 | B37: ='Formation Energies'!S22 -> 0 | C37: ='Formation Energies'!Q22 -> -114.87584 | D37: = | E37: =C37-B37 -> -114.87584 | F37: =IF(ISBLANK(B37),"Pending",IF(E37>0,"CANNOT reduce","CAN reduce")) -> CAN reduce
A39: ΔG_rxn at 1527°C (1800 K)
A40: Oxide | B40: ΔGf(oxide) kJ | C40: ΔGf(Cu₂O) kJ | E40: ΔG_rxn kJ | F40: Verdict
A41: CeO2 | B41: ='Formation Energies'!B28 -> -1328.1808 | C41: ='Formation Energies'!Q28 -> -87.468853 | D41: = | E41: =C41-B41 -> 1240.712 | F41: =IF(ISBLANK(B41),"Pending",IF(E41>0,"CANNOT reduce","CAN reduce")) -> CANNOT reduce
A42: CaO | B42: ='Formation Energies'!C28 -> -878.77799 | C42: ='Formation Energies'!Q28 -> -87.468853 | D42: = | E42: =C42-B42 -> 791.30914 | F42: =IF(ISBLANK(B42),"Pending",IF(E42>0,"CANNOT reduce","CAN reduce")) -> CANNOT reduce
...

Sheet Normalization Explained
A1: HOW TC-PYTHON VALUES ARE NORMALIZED
A3: Thermo-Calc reports GM = Gibbs energy per mole of ATOMS
A4: We need: ΔGf per mole of O₂ (for Ellingham comparison)
A6: Step 1: GM (J/mol atoms) × atoms_per_formula = G per formula unit
A7: Step 2: G per formula / oxide_per_O₂ = ΔGf per mol O₂
A9: STOICHIOMETRY TABLE
A10: Oxide | B10: Atoms | C10: Balanced Reaction | D10: oxide/O₂
A11: Cu₂O | B11: 3 | C11: 4Cu + O₂ → 2Cu₂O | D11: 2
A12: Al₂O₃ | B12: 5 | C12: 4/3 Al + O₂ → 2/3 Al₂O₃ | D12: 0.667
A13: MgO | B13: 2 | C13: 2Mg + O₂ → 2MgO | D13: 2
A14: SiO₂ | B14: 3 | C14: Si + O₂ → SiO₂ | D14: 1
A15: TiO₂ | B15: 3 | C15: Ti + O₂ → TiO₂ | D15: 1
A16: FeO | B16: 2 | C16: 2Fe + O₂ → 2FeO | D16: 2
A17: CaO | B17: 2 | C17: 2Ca + O₂ → 2CaO | D17: 2
A18: V₂O₅ | B18: 7 | C18: 4/5 V + O₂ → 2/5 V₂O₅ | D18: 0.4
A19: B₂O₃ | B19: 5 | C19: 4/3 B + O₂ → 2/3 B₂O₃ | D19: 0.667
A20: La₂O₃ | B20: 5 | C20: 4/3 La + O₂ → 2/3 La₂O₃ | D20: 0.667
A21: CeO₂ | B21: 3 | C21: Ce + O₂ → CeO₂ | D21: 1

Sheet Complete Screening Table
A1: Oxide | B1: Density | C1: Tm (°C) | D1: Floats? | E1: Solid? | F1: ΔG 727°C | G1: ΔG 1227°C | H1: ΔG 1527°C | I1: Reducible? | J1: $/g | K1: Toxicity | L1: Source
A2: CeO2 | B2: 7.22 | C2: 2400 | D2: No | E2: Yes | F2: 997.17641 | G2: 1156.3101 | H2: 1240.712 | I2: No | J2: 0.006 | K2: Low | L2: SSUB3
A3: CaO | B3: 3.34 | C3: 2613 | D3: Yes | E3: Yes | F3: 870.21922 | G3: 836.44032 | H3: 791.30914 | I3: No | J3: 0.0002 | K3: Low | L3: TCOX14
A4: La2O3 | B4: 6.51 | C4: 2315 | D4: Yes | E4: Yes | F4: 812.99324 | G4: 795.18553 | H4: 766.27908 | I4: No | J4: 0.01 | K4: Low-Moderate | L4: TCOX14
A5: MgO | B5: 3.58 | C5: 2852 | D5: Yes | E5: Yes | F5: 795.95262 | G5: 736.48802 | H5: 642.86203 | I5: No | J5: 0.0003 | K5: Low | L5: TCOX14
A6: ZrO2 | B6: 5.68 | C6: 2715 | D6: Yes | E6: Yes | F6: 718.59323 | G6: 702.06652 | H6: 675.69928 | I6: No | J6: 0.035 | K6: Low | L6: TCOX14
A7: Al2O3 | B7: 3.95 | C7: 2072 | D7: Yes | E7: Yes | F7: 716.71731 | G7: 682.66871 | H7: 644.82222 | I7: No | J7: 0.0005 | K7: Low | L7: TCOX14
A8: TiO2 | B8: 4.23 | C8: 1843 | D8: Yes | E8: Yes | F8: 569.38895 | G8: 556.66791 | H8: 531.29819 | I8: No | J8: 0.003 | K8: Low | L8: TCOX14
A9: SiO2 | B9: 2.65 | C9: 1713 | D9: Yes | E9: Yes | F9: 539.36968 | G9: 529.42765 | H9: 502.72049 | I9: No | J9: 5e-05 | K9: Low (silicosis) | L9: TCOX14
A10: MnO | B10: 5.43 | C10: 1842 | D10: Yes | E10: Yes | F10: 434.06714 | G10: 433.90324 | H10: 408.89402 | I10: No | J10: 0.005 | K10: Low | L10: TCOX14
A11: Cr2O3 | B11: 5.22 | C11: 2435 | D11: Yes | E11: Yes | F11: 385.69328 | G11: 377.81507 | H11: 354.83896 | I11: No | J11: 0.005 | K11: Moderate (Cr VI) | L11: TCOX14
A12: V2O5 | B12: 3.36 | C12: 690 | D12: Yes | E12: LIQUID | F12: 257.21866 | G12: 266.99826 | H12: 259.41768 | I12: No | J12: 0.011 | K12: HIGH - Carc. 1B | L12: TCOX14
A13: FeO | B13: 5.74 | C13: 1377 | D13: Yes | E13: LIQUID | F13: 220.37862 | G13: 230.73422 | H13: 213.80798 | I13: No | J13: 0.0009 | K13: Low | L13: TCOX14
... A17: CuO | B17: 6.31 | C17: 1326 | D17: Yes | E17: LIQUID | F17: -58.805891 | G17: -51.731286 | H17: -40.990156 | I17: Trivially | J17: 0.008 | K17: Moderate - aquatic | L17: TCOX14
A18: B2O3 | B18: 2.55 | C18: 450 | D18: Yes | E18: LIQUID | F18: Pending | G18: Pending | H18: 481.10417 | I18: No | J18: 0.003 | K18: Moderate - Repr.1B | L18: TCOX14 (partial)

Sheet Pricing & SDS
A1: Oxide | B1: CAS | C1: Lab $/g | D1: Industrial $/g | E1: Sigma # | F1: SDS Link | G1: Hazard
A2: CeO2 | B2: 1306-38-3 | C2: 0.9 | D2: 0.006 | E2: 211575 | F2: https://www.sigmaaldrich.com/US/en/product/aldrich/211575 | G2: Low
A3: CaO | B3: 1305-78-8 | C3: 0.16 | D3: 0.0002 | E3: 248568 | F3: https://www.sigmaaldrich.com/US/en/product/aldrich/248568 | G3: Low
A4: La2O3 | B4: 1312-81-8 | C4: 1.25 | D4: 0.01 | E4: L4000 | F4: https://www.sigmaaldrich.com/US/en/product/aldrich/L4000 | G4: Low-Moderate
A5: MgO | B5: 1309-48-4 | C5: 0.13 | D5: 0.0003 | E5: 529699 | F5: https://www.sigmaaldrich.com/US/en/product/aldrich/529699 | G5: Low
A6: ZrO2 | B6: 1314-23-4 | C6: 0.67 | D6: 0.035 | E6: 230693 | F6: https://www.sigmaaldrich.com/US/en/product/aldrich/230693 | G6: Low
A7: Al2O3 | B7: 1344-28-1 | C7: 0.09 | D7: 0.0005 | E7: 11028 | F7: https://www.sigmaaldrich.com/US/en/product/aldrich/11028 | G7: Low
A8: TiO2 | B8: 13463-67-7 | C8: 0.29 | D8: 0.003 | E8: 14021 | F8: https://www.sigmaaldrich.com/US/en/product/aldrich/14021 | G8: Low
A9: SiO2 | B9: 7631-86-9 | C9: 0.1 | D9: 5e-05 | E9: 637238 | F9: https://www.sigmaaldrich.com/US/en/product/aldrich/637238 | G9: Low (silicosis)
A10: MnO | B10: 1344-43-0 | C10: 0.55 | D10: 0.005 | E10: 377201 | F10: https://www.sigmaaldrich.com/US/en/product/aldrich/377201 | G10: Low
A11: Cr2O3 | B11: 1308-38-9 | C11: 2.38 | D11: 0.005 | E11: 393703 | F11: https://www.sigmaaldrich.com/US/en/product/aldrich/393703 | G11: Moderate (Cr VI)
A12: V2O5 | B12: 1314-62-1 | C12: 1 | D12: 0.011 | E12: 221899 | F12: https://www.sigmaaldrich.com/US/en/product/aldrich/221899 | G12: HIGH - Carc. 1B
A13: FeO | B13: 1345-25-1 | C13: 0.75 | D13: 0.0009 | E13: 400866 | F13: https://www.sigmaaldrich.com/US/en/product/aldrich/400866 | G13: Low
... A19: B2O3 | B19: 1303-86-2 | C19: 1.09 | D19: 0.003 | E19: 339075 | F19: https://www.sigmaaldrich.com/US/en/product/aldrich/339075 | G19: Moderate - Repr.1B

Sheet Moonshot Candidates
A1: Oxide | B1: Priority | C1: ΔG_rxn 1527°C | D1: Mechanism | E1: Evidence | F1: DB Source | G1: Status
A2: V₂O₅ | B2: HIGH | C2: +259.4 kJ | D2: Copper vanadate CuV₂O₆ formation | E2: Bureau of Mines: 40-60% Cu removal at 1200-1400°C | F2: TCOX14 | G2: Complete
A3: B₂O₃ | B3: HIGH | C3: partial | D3: Cu₂O dissolves into borate slag | E3: Partition coefficient >10 for Cu₂O in borate melts | F3: TCOX14 (7pts) | G3: Partial
A4: CeO₂ | B4: HIGH | C4: +1240.7 kJ | D4: Ce⁴⁺/Ce³⁺ redox shuttling | E4: Oxygen carrier in catalysis; low toxicity | F4: SSUB3 | G4: Complete*
A5: La₂O₃ | B5: MEDIUM | C5: +766.3 kJ | D5: Cuprate La₂CuO₄ formation | E5: Superconductor lit. proves La₂O₃ + Cu → La₂CuO₄ | F5: TCOX14 | G5: Complete
A6: NiO | B6: LOW | C6: +76.0 kJ | D6: Reference (co-tramp) | E6: Confirms position near Cu₂O on Ellingham | F6: TCOX14 | G6: Complete
A7: CoO | B7: LOW | C7: +126.6 kJ | D7: Reference (co-contaminant) | E7: Between FeO and NiO as expected | F7: TCOX14 | G7: Complete
A8: PbO | B8: LOW | C8: +136.2 kJ | D8: Reference (co-tramp) | E8: Cu CAN reduce PbO at <727°C; not at steelmaking temps | F8: SSUB3 | G8: Complete*
A10: * SSUB3 values flagged: PbO 35% off literature, CeO₂ 19% off. Use with caution.
