Workbook

Sheet dG_vs_T
A1: T (K) | B1: T (°C) | C1: dG CuFe2O4 (kJ) | D1: dG Cu3V2O8 (kJ) | E1: dG CuMn2O4 (kJ) | F1: dG Cu2SiO4 (kJ) | G1: dG CuB2O4 (kJ) | H1: dG CuAl2O4 (kJ)
A2: 800 | B2: =A2-273.15 -> 526.85 | C2: -271.03187 | D2: -249.13507 | E2: -197.65667 | F2: -166.05035 | G2: -96.858042 | H2: -86.81767
A3: 825 | B3: =A3-273.15 -> 551.85 | C3: -267.09329 | D3: -242.7202 | E3: -193.09773 | F3: -161.77444 | G3: -94.686285 | H3: -85.012388
A4: 850 | B4: =A4-273.15 -> 576.85 | C4: -262.71414 | D4: -236.32544 | E4: -188.56291 | F4: -157.51194 | G4: -92.521221 | H4: -83.217677
A5: 875 | B5: =A5-273.15 -> 601.85 | C5: -258.16753 | D5: -229.95029 | E5: -184.05175 | F5: -153.26252 | G5: -90.362684 | H5: -81.433531
A6: 900 | B6: =A6-273.15 -> 626.85 | C6: -253.63898 | D6: -223.59432 | E6: -179.56374 | F6: -149.02588 | G6: -88.210506 | H6: -79.659947
A7: 925 | B7: =A7-273.15 -> 651.85 | C7: -249.12785 | D7: -217.25708 | E7: -175.09838 | F7: -144.80172 | G7: -86.064517 | H7: -77.896921
A8: 950 | B8: =A8-273.15 -> 676.85 | C8: -244.63346 | D8: -210.93818 | E8: -170.65513 | F8: -140.58978 | G8: -83.924531 | H8: -76.144449
A9: 975 | B9: =A9-273.15 -> 701.85 | C9: -240.15527 | D9: -204.86912 | E9: -166.2335 | F9: -136.38981 | G9: -81.790328 | H9: -74.402526
A10: 1000 | B10: =A10-273.15 -> 726.85 | C10: -235.69271 | D10: -198.67769 | E10: -161.83298 | F10: -132.20156 | G10: -79.661614 | H10: -72.671147
A11: 1025 | B11: =A11-273.15 -> 751.85 | C11: -231.24518 | D11: -192.53253 | E11: -157.45305 | F11: -128.02481 | G11: -77.537947 | H11: -70.950302
A12: 1050 | B12: =A12-273.15 -> 776.85 | C12: -226.81218 | E12: -153.09322 | F12: -123.85934 | G12: -75.419088 | H12: -69.23998
A13: 1075 | B13: =A13-273.15 -> 801.85 | C13: -222.39372 | D13: -180.41697 | E13: -148.75302 | F13: -119.70494 | G13: -73.305701 | H13: -67.540164
A14: 1100 | B14: =A14-273.15 -> 826.85 | C14: -217.98972 | D14: -174.4734 | E14: -144.43196 | F14: -115.56141 | G14: -71.197753 | H14: -65.850837
A15: 1125 | B15: =A15-273.15 -> 851.85 | C15: -213.60006 | D15: -168.63326 | E15: -140.1296 | F15: -111.42856 | G15: -69.095149 | H15: -64.171972
A16: 1150 | B16: =A16-273.15 -> 876.85 | C16: -209.22461 | D16: -162.92829 | E16: -135.84549 | F16: -107.30622 | G16: -66.997798 | H16: -62.503541
A17: 1175 | B17: =A17-273.15 -> 901.85 | C17: -204.86274 | D17: -157.40501 | E17: -131.5792 | F17: -103.19422 | G17: -64.905612 | H17: -60.845508
A18: 1200 | B18: =A18-273.15 -> 926.85 | C18: -200.51353 | D18: -152.13309 | E18: -127.33033 | F18: -99.092366 | G18: -62.818505 | H18: -59.19783
A19: 1225 | B19: =A19-273.15 -> 951.85 | C19: -196.17862 | E19: -123.09847 | F19: -95.000499 | G19: -60.736394 | H19: -57.56046
A20: 1250 | B20: =A20-273.15 -> 976.85 | C20: -191.85794 | D20: -142.83948 | E20: -118.88325 | F20: -90.918454 | G20: -58.659195 | H20: -55.933339
A21: 1275 | B21: =A21-273.15 -> 1001.85 | C21: -187.55146 | E21: -114.6843 | F21: -86.846092 | G21: -56.586841 | H21: -54.316415
A22: 1300 | B22: =A22-273.15 -> 1026.85 | C22: -183.25921 | E22: -110.50135 | F22: -82.78339 | G22: -54.519319 | H22: -52.709684
A23: 1325 | B23: =A23-273.15 -> 1051.85 | C23: -178.9812 | E23: -106.33408 | F23: -78.730243 | G23: -53.054238 | H23: -51.113091
A24: 1350 | B24: =A24-273.15 -> 1076.85 | C24: -174.71743 | D24: -135.64175 | E24: -102.1822 | F24: -74.686534 | G24: -53.009006 | H24: -49.526567
A25: 1375 | B25: =A25-273.15 -> 1101.85 | C25: -170.36264 | D25: -134.4008 | E25: -97.876797 | F25: -71.801833 | G25: -52.792429 | H25: -47.779646
A26: 1400 | B26: =A26-273.15 -> 1126.85 | C26: -166.00869 | D26: -132.93628 | E26: -93.632385 | F26: -70.550312 | G26: -52.500641 | H26: -45.968408
A27: 1425 | B27: =A27-273.15 -> 1151.85 | C27: -161.73569 | D27: -131.46934 | E27: -89.608759 | F27: -69.309585 | G27: -52.207472 | H27: -44.166741
A28: 1450 | B28: =A28-273.15 -> 1176.85 | C28: -157.56456 | D28: -129.99994 | E28: -85.836398 | F28: -68.079849 | G28: -51.91301 | H28: -42.375021
A29: 1475 | B29: =A29-273.15 -> 1201.85 | C29: -153.51566 | D29: -128.52803 | E29: -82.351275 | F29: -66.861311 | G29: -51.617344 | H29: -40.594077
A30: 1500 | B30: =A30-273.15 -> 1226.85 | C30: -149.60506 | D30: -127.05356 | E30: -79.185533 | F30: -65.654197 | G30: -51.320558 | H30: -38.82568
A31: 1525 | B31: =A31-273.15 -> 1251.85 | C31: -145.84286 | D31: -125.57651 | E31: -76.354681 | F31: -64.458769 | G31: -51.02274 | H31: -37.073522
A32: 1550 | B32: =A32-273.15 -> 1276.85 | C32: -142.23488 | D32: -124.09684 | E32: -73.850637 | F32: -63.275341 | G32: -50.723975 | H32: -35.345136
A33: 1575 | B33: =A33-273.15 -> 1301.85 | C33: -138.78654 | D33: -122.61453 | E33: -71.64969 | F33: -62.104293 | G33: -50.424355 | H33: -34.701742
A34: 1600 | B34: =A34-273.15 -> 1326.85 | C34: -135.50662 | D34: -121.12956 | E34: -69.728239 | F34: -60.946092 | G34: -50.123975 | H34: -34.366378
A35: 1625 | B35: =A35-273.15 -> 1351.85 | C35: -132.4104 | D35: -119.64191 | E35: -68.073494 | F35: -59.801294 | G35: -49.822945 | H35: -34.045858
A36: 1650 | B36: =A36-273.15 -> 1376.85 | C36: -129.29344 | D36: -118.15157 | E36: -66.687424 | F36: -58.670551 | G36: -49.521384 | H36: -33.740897
A37: 1675 | B37: =A37-273.15 -> 1401.85 | C37: -125.64358 | E37: -65.588488 | F37: -57.554595 | G37: -49.219437 | H37: -33.452457
A38: 1700 | B38: =A38-273.15 -> 1426.85 | C38: -122.2905 | D38: -115.16285 | E38: -64.814796 | F38: -56.454201 | G38: -48.917274 | H38: -33.181787
A39: 1725 | B39: =A39-273.15 -> 1451.85 | C39: -119.33028 | D39: -113.66449 | E39: -64.431384 | F39: -55.370168 | G39: -48.615106 | H39: -32.930463
A40: 1750 | B40: =A40-273.15 -> 1476.85 | C40: -116.77672 | D40: -112.16349 | E40: -64.398131 | F40: -54.302418 | G40: -48.313194 | H40: -32.700449
...

Sheet CuFe2O4_Decomposition
A1: T (K) | B1: T (°C) | C1: dG_original (kJ) | D1: dG_alternative (kJ) | E1: dG_Fe_oxidation (kJ) | F1: Cu_capture (%)
A2: 800 | B2: =A2-273.15 -> 526.85 | C2: -271.03187 | D2: -85.340853 | E2: =C2-D2 -> -185.69102 | F2: =D2/C2*100 -> 31.487386
A3: 850 | B3: =A3-273.15 -> 576.85 | C3: -262.71414 | D3: -82.376584 | E3: =C3-D3 -> -180.33756 | F3: =D3/C3*100 -> 31.355976
A4: 900 | B4: =A4-273.15 -> 626.85 | C4: -253.63898 | D4: -79.384097 | E4: =C4-D4 -> -174.25488 | F4: =D4/C4*100 -> 31.298066
A5: 950 | B5: =A5-273.15 -> 676.85 | C5: -244.63346 | D5: -76.337724 | E5: =C5-D5 -> -168.29574 | F5: =D5/C5*100 -> 31.20494
A6: 1000 | B6: =A6-273.15 -> 726.85 | C6: -235.69271 | D6: -73.247969 | E6: =C6-D6 -> -162.44474 | F6: =D6/C6*100 -> 31.077741
A7: 1050 | B7: =A7-273.15 -> 776.85 | C7: -226.81218 | D7: -70.178773 | E7: =C7-D7 -> -156.6334 | F7: =D7/C7*100 -> 30.94136
A8: 1100 | B8: =A8-273.15 -> 826.85 | C8: -217.98972 | D8: -67.143947 | E8: =C8-D8 -> -150.84578 | F8: =D8/C8*100 -> 30.801428
A9: 1150 | B9: =A9-273.15 -> 876.85 | C9: -209.22461 | D9: -64.151393 | E9: =C9-D9 -> -145.07321 | F9: =D9/C9*100 -> 30.661495
A10: 1200 | B10: =A10-273.15 -> 926.85 | C10: -200.51353 | D10: -61.206737 | E10: =C10-D10 -> -139.30679 | F10: =D10/C10*100 -> 30.524992
A11: 1250 | B11: =A11-273.15 -> 976.85 | C11: -191.85794 | D11: -58.314513 | E11: =C11-D11 -> -133.54343 | F11: =D11/C11*100 -> 30.394631
A12: 1300 | B12: =A12-273.15 -> 1026.85 | C12: -183.25921 | D12: -55.478722 | E12: =C12-D12 -> -127.78049 | F12: =D12/C12*100 -> 30.27336
A13: 1350 | B13: =A13-273.15 -> 1076.85 | C13: -174.71743 | D13: -52.703069 | E13: =C13-D13 -> -122.01436 | F13: =D13/C13*100 -> 30.164746
... A24: 1900 | B24: =A24-273.15 -> 1626.85 | C24: -102.69378 | D24: -46.715289 | E24: =C24-D24 -> -55.978493 | F24: =D24/C24*100 -> 45.489891

Sheet Activity_Correction
A1: ACTIVITY CORRECTION PARAMETERS
A2: Parameter | B2: Symbol | C2: Value | D2: Unit / Note
A3: Cu mole fraction in steel | B3: X_Cu | C3: 0.003 | D3: ~0.3 wt% Cu
A4: Raoultian activity coefficient | B4: γ_Cu | C4: 8.5 | D4: Literature range: 5-13
A5: Cu activity in liquid Fe | B5: a_Cu | C5: =C3*C4 -> 0.0255 | D5: X_Cu × γ_Cu
A6: Temperature | B6: T | C6: 1800 | D6: K (steelmaking)
A7: Gas constant | B7: R | C7: 8.314 | D7: J/(mol·K)
A8: Penalty per Cu atom consumed | B8: -RT·ln(a_Cu) | C8: =-C7*C6*LN(C5)/1000 -> 54.908469 | D8: kJ/mol (positive = less favorable)
A10: ACTIVITY-CORRECTED ΔG AT 1800 K
A11: Product | B11: Parent Oxide | C11: n_Cu | D11: ΔG° (kJ) | E11: Cu Penalty (kJ) | F11: ΔG_eff (kJ) | G11: Verdict | H11: ΔG per Cu (kJ)
A12: CuFe2O4 | B12: FeO | C12: 1 | D12: -111.88 | E12: =C12*$C$8 -> 54.908469 | F12: =D12+E12 -> -56.971531 | G12: =IF(F12<-10,"ROBUST",IF(F12<0,"MARGINAL",IF(F12<15,"UNCERTAIN","UNFAVORABLE"))) -> ROBUST | H12: =D12/C12 -> -111.88
A13: CuMn2O4 | B13: MnO | C13: 1 | D13: -64.44 | E13: =C13*$C$8 -> 54.908469 | F13: =D13+E13 -> -9.5315315 | G13: =IF(F13<-10,"ROBUST",IF(F13<0,"MARGINAL",IF(F13<15,"UNCERTAIN","UNFAVORABLE"))) -> MARGINAL | H13: =D13/C13 -> -64.44
A14: CuB2O4 | B14: B2O3 | C14: 1 | D14: -47.71 | E14: =C14*$C$8 -> 54.908469 | F14: =D14+E14 -> 7.1984685 | G14: =IF(F14<-10,"ROBUST",IF(F14<0,"MARGINAL",IF(F14<15,"UNCERTAIN","UNFAVORABLE"))) -> UNCERTAIN | H14: =D14/C14 -> -47.71
A15: CuV2O6 | B15: V2O5 | C15: 1 | D15: -44.98 | E15: =C15*$C$8 -> 54.908469 | F15: =D15+E15 -> 9.9284685 | G15: =IF(F15<-10,"ROBUST",IF(F15<0,"MARGINAL",IF(F15<15,"UNCERTAIN","UNFAVORABLE"))) -> UNCERTAIN | H15: =D15/C15 -> -44.98
A16: CuAl2O4 | B16: Al2O3 | C16: 1 | D16: -32.31 | E16: =C16*$C$8 -> 54.908469 | F16: =D16+E16 -> 22.598469 | G16: =IF(F16<-10,"ROBUST",IF(F16<0,"MARGINAL",IF(F16<15,"UNCERTAIN","UNFAVORABLE"))) -> UNFAVORABLE | H16: =D16/C16 -> -32.31
A17: Cu3V2O8 | B17: V2O5 | C17: 3 | D17: -109.15 | E17: =C17*$C$8 -> 164.72541 | F17: =D17+E17 -> 55.575406 | G17: =IF(F17<-10,"ROBUST",IF(F17<0,"MARGINAL",IF(F17<15,"UNCERTAIN","UNFAVORABLE"))) -> UNFAVORABLE | H17: =D17/C17 -> -36.383333
A18: Cu2SiO4 | B18: SiO2 | C18: 2 | D18: -52.21 | E18: =C18*$C$8 -> 109.81694 | F18: =D18+E18 -> 57.606937 | G18: =IF(F18<-10,"ROBUST",IF(F18<0,"MARGINAL",IF(F18<15,"UNCERTAIN","UNFAVORABLE"))) -> UNFAVORABLE | H18: =D18/C18 -> -26.105
A20: γ_Cu SENSITIVITY ANALYSIS
A21: Change γ_Cu in cell C4 above to see all corrections update automatically.
A22: γ_Cu | B22: a_Cu | C22: Penalty/Cu (kJ) | D22: ΔG_eff CuFe2O4 | E22: ΔG_eff CuMn2O4 | F22: ΔG_eff CuB2O4 | G22: ΔG_eff CuV2O6 | H22: ΔG_eff CuAl2O4 | I22: ΔG_eff Cu3V2O8 | J22: ΔG_eff Cu2SiO4
A23: 3 | B23: =A23*$C$3 -> 0.009 | C23: =-$C$7*$C$6*LN(B23)/1000 -> 70.494034 | D23: =-111.88+1*C23 -> -41.385966 | E23: =-64.44+1*C23 -> 6.0540341 | F23: =-47.71+1*C23 -> 22.784034 | G23: =-44.98+1*C23 -> 25.514034 | H23: =-32.31+1*C23 -> 38.184034 | I23: =-109.15+3*C23 -> 102.3321 | J23: =-52.21+2*C23 -> 88.778068
A24: 4 | B24: =A24*$C$3 -> 0.012 | C24: =-$C$7*$C$6*LN(B24)/1000 -> 66.188814 | D24: =-111.88+1*C24 -> -45.691186 | E24: =-64.44+1*C24 -> 1.7488143 | F24: =-47.71+1*C24 -> 18.478814 | G24: =-44.98+1*C24 -> 21.208814 | H24: =-32.31+1*C24 -> 33.878814 | I24: =-109.15+3*C24 -> 89.416443 | J24: =-52.21+2*C24 -> 80.167629
A25: 5 | B25: =A25*$C$3 -> 0.015 | C25: =-$C$7*$C$6*LN(B25)/1000 -> 62.849426 | D25: =-111.88+1*C25 -> -49.030574 | E25: =-64.44+1*C25 -> -1.5905736 | F25: =-47.71+1*C25 -> 15.139426 | G25: =-44.98+1*C25 -> 17.869426 | H25: =-32.31+1*C25 -> 30.539426 | I25: =-109.15+3*C25 -> 79.398279 | J25: =-52.21+2*C25 -> 73.488853
A26: 6 | B26: =A26*$C$3 -> 0.018 | C26: =-$C$7*$C$6*LN(B26)/1000 -> 60.120948 | D26: =-111.88+1*C26 -> -51.759052 | E26: =-64.44+1*C26 -> -4.3190521 | F26: =-47.71+1*C26 -> 12.410948 | G26: =-44.98+1*C26 -> 15.140948 | H26: =-32.31+1*C26 -> 27.810948 | I26: =-109.15+3*C26 -> 71.212844 | J26: =-52.21+2*C26 -> 68.031896
A27: 7 | B27: =A27*$C$3 -> 0.021 | C27: =-$C$7*$C$6*LN(B27)/1000 -> 57.814052 | D27: =-111.88+1*C27 -> -54.065948 | E27: =-64.44+1*C27 -> -6.6259479 | F27: =-47.71+1*C27 -> 10.104052 | G27: =-44.98+1*C27 -> 12.834052 | H27: =-32.31+1*C27 -> 25.504052 | I27: =-109.15+3*C27 -> 64.292156 | J27: =-52.21+2*C27 -> 63.418104
A28: 8 | B28: =A28*$C$3 -> 0.024 | C28: =-$C$7*$C$6*LN(B28)/1000 -> 55.815728 | D28: =-111.88+1*C28 -> -56.064272 | E28: =-64.44+1*C28 -> -8.6242719 | F28: =-47.71+1*C28 -> 8.1057281 | G28: =-44.98+1*C28 -> 10.835728 | H28: =-32.31+1*C28 -> 23.505728 | I28: =-109.15+3*C28 -> 58.297184 | J28: =-52.21+2*C28 -> 59.421456
A29: 8.5 | B29: =A29*$C$3 -> 0.0255 | C29: =-$C$7*$C$6*LN(B29)/1000 -> 54.908469 | D29: =-111.88+1*C29 -> -56.971531 | E29: =-64.44+1*C29 -> -9.5315315 | F29: =-47.71+1*C29 -> 7.1984685 | G29: =-44.98+1*C29 -> 9.9284685 | H29: =-32.31+1*C29 -> 22.598469 | I29: =-109.15+3*C29 -> 55.575406 | J29: =-52.21+2*C29 -> 57.606937
A30: 9 | B30: =A30*$C$3 -> 0.027 | C30: =-$C$7*$C$6*LN(B30)/1000 -> 54.053081 | D30: =-111.88+1*C30 -> -57.826919 | E30: =-64.44+1*C30 -> -10.386919 | F30: =-47.71+1*C30 -> 6.3430814 | G30: =-44.98+1*C30 -> 9.0730814 | H30: =-32.31+1*C30 -> 21.743081 | I30: =-109.15+3*C30 -> 53.009244 | J30: =-52.21+2*C30 -> 55.896163
A31: 10 | B31: =A31*$C$3 -> 0.03 | C31: =-$C$7*$C$6*LN(B31)/1000 -> 52.47634 | D31: =-111.88+1*C31 -> -59.40366 | E31: =-64.44+1*C31 -> -11.96366 | F31: =-47.71+1*C31 -> 4.7663402 | G31: =-44.98+1*C31 -> 7.4963402 | H31: =-32.31+1*C31 -> 20.16634 | I31: =-109.15+3*C31 -> 48.279021 | J31: =-52.21+2*C31 -> 52.74268
A32: 11 | B32: =A32*$C$3 -> 0.033 | C32: =-$C$7*$C$6*LN(B32)/1000 -> 51.050004 | D32: =-111.88+1*C32 -> -60.829996 | E32: =-64.44+1*C32 -> -13.389996 | F32: =-47.71+1*C32 -> 3.3400043 | G32: =-44.98+1*C32 -> 6.0700043 | H32: =-32.31+1*C32 -> 18.740004 | I32: =-109.15+3*C32 -> 44.000013 | J32: =-52.21+2*C32 -> 49.890009
A33: 12 | B33: =A33*$C$3 -> 0.036 | C33: =-$C$7*$C$6*LN(B33)/1000 -> 49.747862 | D33: =-111.88+1*C33 -> -62.132138 | E33: =-64.44+1*C33 -> -14.692138 | F33: =-47.71+1*C33 -> 2.0378617 | G33: =-44.98+1*C33 -> 4.7678617 | H33: =-32.31+1*C33 -> 17.437862 | I33: =-109.15+3*C33 -> 40.093585 | J33: =-52.21+2*C33 -> 47.285723
A34: 13 | B34: =A34*$C$3 -> 0.039 | C34: =-$C$7*$C$6*LN(B34)/1000 -> 48.550007 | D34: =-111.88+1*C34 -> -63.329993 | E34: =-64.44+1*C34 -> -15.889993 | F34: =-47.71+1*C34 -> 0.84000655 | G34: =-44.98+1*C34 -> 3.5700066 | H34: =-32.31+1*C34 -> 16.240007 | I34: =-109.15+3*C34 -> 36.50002 | J34: =-52.21+2*C34 -> 44.890013
A35: 15 | B35: =A35*$C$3 -> 0.045 | C35: =-$C$7*$C$6*LN(B35)/1000 -> 46.408474 | D35: =-111.88+1*C35 -> -65.471526 | E35: =-64.44+1*C35 -> -18.031526 | F35: =-47.71+1*C35 -> -1.3015262 | G35: =-44.98+1*C35 -> 1.4284738 | H35: =-32.31+1*C35 -> 14.098474 | I35: =-109.15+3*C35 -> 30.075421 | J35: =-52.21+2*C35 -> 40.606948
A37: NOTE: V₂O₅ can form either Cu₃V₂O₈ (3 Cu, ΔG° = -109.2 kJ) or CuV₂O₆ (1 Cu, ΔG° = -45.0 kJ). Under dilute Cu conditions, CuV₂O₆ is preferred because the 3× penalty makes Cu₃V₂O₈ unfavorable.
A38: Bureau of Mines (1960s) used ~1 wt% Cu (a_Cu ≈ 0.13), where both V₂O₅ products are favorable. Their 40-60% removal is consistent with our model.

Sheet Candidate_Ranking
A1: Product | B1: dG at 1800 K (kJ) | C1: Named Phase | D1: Stable To (K) | E1: Tier
A2: CuFe2O4 | B2: =dG_vs_T!C42 -> -111.8803 | C2: SPINEL#1 | D2: 1700 | E2: Strong
A3: Cu3V2O8 | B3: =dG_vs_T!D42 -> -109.15374 | C3: (liquid) | D3: N/A (liquid) | E3: Strong
A4: CuMn2O4 | B4: =dG_vs_T!E42 -> -64.442552 | C4: SPINEL#1 | D4: 1700 | E4: Strong
A5: Cu2SiO4 | B5: =dG_vs_T!F42 -> -52.214204 | C5: (liquid) | D5: N/A (liquid) | E5: Strong
A6: CuB2O4 | B6: =dG_vs_T!G42 -> -47.711524 | C6: CUB2O4#1 | D6: 1300 | E6: Strong
A7: CuAl2O4 | B7: =dG_vs_T!H42 -> -32.314512 | C7: SPINEL#1 | D7: 1550 | E7: Moderate

Sheet Slag_Effects
A1: System | B1: Ratio Label | C1: Ratio Value | D1: a_Cu | E1: Stable Phases | F1: % Change from Baseline
A2: Cu-Mn-Si-O | B2: MnO:SiO2 | C2: 0.2 | D2: 0.00060242872 | E2: CRISTOBALITE#1; IONIC_LIQ#1; IONIC_LIQ#3 | F2: 0
A3: Cu-Mn-Si-O | B3: MnO:SiO2 | C3: 0.4 | D3: 0.00059216467 | E3: CRISTOBALITE#1; IONIC_LIQ#1; IONIC_LIQ#2 | F3: =(D3-D$2)/D$2*100 -> -1.7037785
A4: Cu-Mn-Si-O | B4: MnO:SiO2 | C4: 0.6 | D4: 0.00058498596 | E4: CRISTOBALITE#1; IONIC_LIQ#1; IONIC_LIQ#2 | F4: =(D4-D$2)/D$2*100 -> -2.8954061
A5: Cu-Mn-Si-O | B5: MnO:SiO2 | C5: 0.8 | D5: 0.00057955787 | E5: CRISTOBALITE#1; IONIC_LIQ#1; IONIC_LIQ#2 | F5: =(D5-D$2)/D$2*100 -> -3.7964406
A6: Cu-Mn-Si-O | B6: MnO:SiO2 | C6: 1 | D6: 0.00057475403 | E6: IONIC_LIQ#1; IONIC_LIQ#2 | F6: =(D6-D$2)/D$2*100 -> -4.5938526
A7: Cu-Mn-Si-O | B7: MnO:SiO2 | C7: 1.2 | D7: 0.00056900861 | E7: IONIC_LIQ#1; IONIC_LIQ#2 | F7: =(D7-D$2)/D$2*100 -> -5.5475625
A8: Cu-Mn-Si-O | B8: MnO:SiO2 | C8: 1.4 | D8: 0.00056239917 | E8: IONIC_LIQ#1; IONIC_LIQ#3 | F8: =(D8-D$2)/D$2*100 -> -6.6446943
A9: Cu-Mn-Si-O | B9: MnO:SiO2 | C9: 1.6 | D9: 0.0005549646 | E9: IONIC_LIQ#1; IONIC_LIQ#2 | F9: =(D9-D$2)/D$2*100 -> -7.8787935
A10: Cu-Mn-Si-O | B10: MnO:SiO2 | C10: 1.8 | D10: 0.00054696205 | E10: IONIC_LIQ#1; IONIC_LIQ#2 | F10: =(D10-D$2)/D$2*100 -> -9.2071763
A11: Cu-Mn-Si-O | B11: MnO:SiO2 | C11: 2 | D11: 0.00053863749 | E11: IONIC_LIQ#1; IONIC_LIQ#2 | F11: =(D11-D$2)/D$2*100 -> -10.589009
A12: Cu-Mn-Si-O | B12: MnO:SiO2 | C12: 2.2 | D12: 0.0005302396 | E12: IONIC_LIQ#1; IONIC_LIQ#3 | F12: =(D12-D$2)/D$2*100 -> -11.983015
A13: Cu-Mn-Si-O | B13: MnO:SiO2 | C13: 2.4 | D13: 0.00052201662 | E13: IONIC_LIQ#1; IONIC_LIQ#2 | F13: =(D13-D$2)/D$2*100 -> -13.347985
A14: Cu-Mn-Si-O | B14: MnO:SiO2 | C14: 2.6 | D14: 0.00051417312 | E14: IONIC_LIQ#1; IONIC_LIQ#2 | F14: =(D14-D$2)/D$2*100 -> -14.649965
... A16: Cu-Mn-Si-O | B16: MnO:SiO2 | C16: 3 | D16: 0.00050010457 | E16: IONIC_LIQ#1; IONIC_LIQ#3 | F16: =(D16-D$2)/D$2*100 -> -16.98527
A17: Cu-Al-Si-O | B17: Al2O3:SiO2 | C17: 0.2 | D17: 0.00062385951 | E17: CRISTOBALITE#1; IONIC_LIQ#1; MULLITE#1 | F17: 0
A18: Cu-Al-Si-O | B18: Al2O3:SiO2 | C18: 0.4 | D18: 0.00062385951 | E18: CRISTOBALITE#1; IONIC_LIQ#1; MULLITE#1 | F18: =(D18-D$17)/D$17*100 -> 0
A19: Cu-Al-Si-O | B19: Al2O3:SiO2 | C19: 0.6 | D19: 0.00062385951 | E19: CRISTOBALITE#1; IONIC_LIQ#1; MULLITE#1 | F19: =(D19-D$17)/D$17*100 -> 3.649579e-13
A20: Cu-Al-Si-O | B20: Al2O3:SiO2 | C20: 0.8 | D20: 0.00062385951 | E20: CRISTOBALITE#1; IONIC_LIQ#1; MULLITE#1 | F20: =(D20-D$17)/D$17*100 -> 3.649579e-13
A21: Cu-Al-Si-O | B21: Al2O3:SiO2 | C21: 1 | D21: 0.00062385951 | E21: CRISTOBALITE#1; IONIC_LIQ#1; MULLITE#1 | F21: =(D21-D$17)/D$17*100 -> 3.649579e-13
A22: Cu-Al-Si-O | B22: Al2O3:SiO2 | C22: 1.2 | D22: 0.00062385951 | E22: CRISTOBALITE#1; IONIC_LIQ#1; MULLITE#1 | F22: =(D22-D$17)/D$17*100 -> 8.6894737e-14
A23: Cu-Al-Si-O | B23: Al2O3:SiO2 | C23: 1.4 | D23: 0.00062385951 | E23: CRISTOBALITE#1; IONIC_LIQ#1; MULLITE#1 | F23: =(D23-D$17)/D$17*100 -> 8.6894737e-14
A24: Cu-Al-Si-O | B24: Al2O3:SiO2 | C24: 1.6 | D24: 0.000624011 | E24: IONIC_LIQ#1; MULLITE#1 | F24: =(D24-D$17)/D$17*100 -> 0.0242826
A25: Cu-Al-Si-O | B25: Al2O3:SiO2 | C25: 1.8 | D25: 0.00062407644 | E25: CORUNDUM#1; IONIC_LIQ#1; MULLITE#1 | F25: =(D25-D$17)/D$17*100 -> 0.034771612
A26: Cu-Al-Si-O | B26: Al2O3:SiO2 | C26: 2 | D26: 0.00062407644 | E26: CORUNDUM#1; IONIC_LIQ#1; MULLITE#1 | F26: =(D26-D$17)/D$17*100 -> 0.034771612
A27: Cu-Al-Si-O | B27: Al2O3:SiO2 | C27: 2.2 | D27: 0.00062407644 | E27: CORUNDUM#1; IONIC_LIQ#1; MULLITE#1 | F27: =(D27-D$17)/D$17*100 -> 0.034771612
A28: Cu-Al-Si-O | B28: Al2O3:SiO2 | C28: 2.4 | D28: 0.00062407644 | E28: CORUNDUM#1; IONIC_LIQ#1; MULLITE#1 | F28: =(D28-D$17)/D$17*100 -> 0.034771612
A29: Cu-Al-Si-O | B29: Al2O3:SiO2 | C29: 2.6 | D29: 0.00062407644 | E29: CORUNDUM#1; IONIC_LIQ#1; MULLITE#1 | F29: =(D29-D$17)/D$17*100 -> 0.034771612
... A31: Cu-Al-Si-O | B31: Al2O3:SiO2 | C31: 3 | D31: 0.00062407644 | E31: CORUNDUM#1; IONIC_LIQ#1; MULLITE#1 | F31: =(D31-D$17)/D$17*100 -> 0.034771612

Sheet Cu_Activity
A1: System | B1: Oxide | C1: T (K) | D1: X_Cu | E1: X_M | F1: X_O | G1: a_Cu | H1: Stable Phases
A2: Cu-Al-O | B2: Al2O3 | C2: 1800 | D2: 0.9 | E2: 0.04 | F2: 0.06 | G2: 0.00062424159 | H2: CORUNDUM#1; IONIC_LIQ#1
A3: Cu-Al-O | B3: Al2O3 | C3: 1800 | D3: 0.855263 | E3: 0.057895 | F3: 0.086842 | G3: 0.00062424159 | H3: CORUNDUM#1; IONIC_LIQ#1
A4: Cu-Al-O | B4: Al2O3 | C4: 1800 | D4: 0.810526 | E4: 0.075789 | F4: 0.113684 | G4: 0.00062424159 | H4: CORUNDUM#1; IONIC_LIQ#1
A5: Cu-Al-O | B5: Al2O3 | C5: 1800 | D5: 0.765789 | E5: 0.093684 | F5: 0.140526 | G5: 0.00062424159 | H5: CORUNDUM#1; IONIC_LIQ#1
A6: Cu-Al-O | B6: Al2O3 | C6: 1800 | D6: 0.721053 | E6: 0.111579 | F6: 0.167368 | G6: 0.00062424159 | H6: CORUNDUM#1; IONIC_LIQ#1
A7: Cu-Al-O | B7: Al2O3 | C7: 1800 | D7: 0.676316 | E7: 0.129474 | F7: 0.194211 | G7: 0.00062424159 | H7: CORUNDUM#1; IONIC_LIQ#1
A8: Cu-Al-O | B8: Al2O3 | C8: 1800 | D8: 0.631579 | E8: 0.147368 | F8: 0.221053 | G8: 0.00062424159 | H8: CORUNDUM#1; IONIC_LIQ#1
A9: Cu-Al-O | B9: Al2O3 | C9: 1800 | D9: 0.586842 | E9: 0.165263 | F9: 0.247895 | G9: 0.00062424159 | H9: CORUNDUM#1; IONIC_LIQ#1
A10: Cu-Al-O | B10: Al2O3 | C10: 1800 | D10: 0.542105 | E10: 0.183158 | F10: 0.274737 | G10: 0.00062424159 | H10: CORUNDUM#1; IONIC_LIQ#1
A11: Cu-Al-O | B11: Al2O3 | C11: 1800 | D11: 0.497368 | E11: 0.201053 | F11: 0.301579 | G11: 0.00062424159 | H11: CORUNDUM#1; IONIC_LIQ#1
A12: Cu-Al-O | B12: Al2O3 | C12: 1800 | D12: 0.452632 | E12: 0.218947 | F12: 0.328421 | G12: 0.00062424159 | H12: CORUNDUM#1; IONIC_LIQ#1
A13: Cu-Al-O | B13: Al2O3 | C13: 1800 | D13: 0.407895 | E13: 0.236842 | F13: 0.355263 | G13: 0.00062424159 | H13: CORUNDUM#1; IONIC_LIQ#1
... A81: Cu-V-O | B81: V2O5 | C81: 1800 | D81: 0.05 | E81: 0.271429 | F81: 0.678571 | G81: 3.3043762e-05 | H81: GAS#1; IONIC_LIQ#2

Sheet Data_Sources
A1: CSV File | B1: Generated By | C1: Database | D1: Description | E1: Date Extracted
A2: dG_vs_T_top6.csv | B2: simulations/tcpython/dG_vs_T_top6.py | C2: TCOX14 | D2: Fine-resolution dG vs T for top 6 ternary candidates (25 K steps, 800-1900 K) | E2: 2026-03-13
A3: cufe2o4_alternative_reaction.csv | B3: simulations/tcpython/cufe2o4_alternative_reaction.py | C3: TCOX14 | D3: CuFe2O4 formation decomposed into Cu-capture vs Fe-oxidation components (50 K steps, 800-1900 K) | E3: 2026-03-13
A4: cufe2o4_decomposition_results.csv | B4: screening/analyze_cufe2o4_decomposition.py | C4: (derived from cufe2o4_alternative_reaction.csv) | D4: Pre-computed Fe-oxidation and Cu-capture percentages | E4: 2026-03-13
A5: slag_composition_effects.csv | B5: simulations/tcpython/slag_composition_effects.py | C5: TCOX14 | D5: Cu activity in quaternary slag systems (Cu-Mn-Si-O, Cu-Al-Si-O) vs basicity ratio at 1800 K | E5: 2026-03-13
A6: cu_activity_vs_oxide.csv | B6: simulations/tcpython/cu_activity_vs_oxide.py | C6: TCOX14 | D6: Cu activity sweep at 1800 K across 4 ternary systems (Cu-Al-O, Cu-Mn-O, Cu-Fe-O, Cu-V-O), 20 compositions each | E6: 2026-03-13
